Workbook

Sheet Dashboard
A1: 📊 IT HELPDESK KPI DASHBOARD
A2: Live Performance Metrics | As of: =TEXT(TODAY(),"DD-MMM-YYYY") | Data Source: Tickets Sheet
A4: 🎫 Total Tickets | E4: 🔓 Open Tickets | I4: ✅ SLA Compliance | M4: ⏱️ Avg Response | Q4: ⭐ CSAT Score
A6: =COUNTA(Tickets!A4:A500)-COUNTBLANK(Tickets!A4:A500) -> -377 | E6: =COUNTIF(Tickets!I:I,"Open")+COUNTIF(Tickets!I:I,"In Progress") -> 19 | I6: =IFERROR(COUNTIF(Tickets!Q:Q,"No")/MAX(COUNTA(Tickets!A4:A500)-COUNTBLANK(Tickets!A4:A500),1),0) -> 30 | M6: =IFERROR(AVERAGEIF(Tickets!O:O,"<>",Tickets!O:O),0) -> 25.1565 | Q6: =IFERROR(AVERAGEIF(Tickets!S:S,"<>",Tickets!S:S),0) -> 3.8333333
E9: Backlog | I9: Target ≥90% | M9: Hours | Q9: / 5.0
A11: 🔴 SLA Breaches | E11: 🔁 Reopen Rate | I11: ⏰ Aging >7 Days | M11: ⚡ Resolved Today | Q11: 📋 P1 Tickets
A13: =COUNTIF(Tickets!Q:Q,"Yes") -> 30 | E13: =IFERROR(COUNTIF(Tickets!I:I,"Reopened")/MAX(COUNTA(Tickets!A4:A500)-COUNTBLANK(Tickets!A4:A500),1),0) -> 3 | I13: =COUNTIFS(Tickets!I:I,"Open",Tickets!B:B,"<="&(TODAY()-7)) -> 7 | M13: =COUNTIFS(Tickets!I:I,"Resolved",Tickets!D:D,TODAY())+COUNTIFS(Tickets!I:I,"Closed",Tickets!E:E,TODAY()) -> 0 | Q13: =COUNTIF(Tickets!F:F,"P1 - Critical") -> 6
A16: Tickets breached | E16: Target <5% | I16: Need escalation | M16: Tickets | Q16: Critical
A18: Status Distribution | E18: Tickets by Category | I18: Technician Workload
A19: Status | B19: Count | E19: Category | F19: Total | G19: SLA Breach | I19: Technician | J19: Open | K19: Resolved
A20: Open | B20: =COUNTIF(Tickets!I:I,A20) -> 7 | E20: Hardware | F20: =COUNTIF(Tickets!G:G,E20) -> 8 | G20: =COUNTIFS(Tickets!G:G,E20,Tickets!Q:Q,"Yes") -> 3 | I20: Ahmed Al-Rashid | J20: =COUNTIFS(Tickets!K:K,I20,Tickets!I:I,"Open") -> 2 | K20: =COUNTIFS(Tickets!K:K,I20,Tickets!I:I,"Resolved")+COUNTIFS(Tickets!K:K,I20,Tickets!I:I,"Closed") -> 6
A21: In Progress | B21: =COUNTIF(Tickets!I:I,A21) -> 12 | E21: Software | F21: =COUNTIF(Tickets!G:G,E21) -> 6 | G21: =COUNTIFS(Tickets!G:G,E21,Tickets!Q:Q,"Yes") -> 4 | I21: Sara Mohammed | J21: =COUNTIFS(Tickets!K:K,I21,Tickets!I:I,"Open") -> 1 | K21: =COUNTIFS(Tickets!K:K,I21,Tickets!I:I,"Resolved")+COUNTIFS(Tickets!K:K,I21,Tickets!I:I,"Closed") -> 5
A22: Resolved | B22: =COUNTIF(Tickets!I:I,A22) -> 15 | E22: Network | F22: =COUNTIF(Tickets!G:G,E22) -> 14 | G22: =COUNTIFS(Tickets!G:G,E22,Tickets!Q:Q,"Yes") -> 8 | I22: Khalid Hassan | J22: =COUNTIFS(Tickets!K:K,I22,Tickets!I:I,"Open") -> 2 | K22: =COUNTIFS(Tickets!K:K,I22,Tickets!I:I,"Resolved")+COUNTIFS(Tickets!K:K,I22,Tickets!I:I,"Closed") -> 10
A23: Closed | B23: =COUNTIF(Tickets!I:I,A23) -> 21 | E23: Access & Security | F23: =COUNTIF(Tickets!G:G,E23) -> 8 | G23: =COUNTIFS(Tickets!G:G,E23,Tickets!Q:Q,"Yes") -> 3 | I23: Fatima Al-Ali | J23: =COUNTIFS(Tickets!K:K,I23,Tickets!I:I,"Open") -> 1 | K23: =COUNTIFS(Tickets!K:K,I23,Tickets!I:I,"Resolved")+COUNTIFS(Tickets!K:K,I23,Tickets!I:I,"Closed") -> 5
A24: Reopened | B24: =COUNTIF(Tickets!I:I,A24) -> 3 | E24: Email & Communication | F24: =COUNTIF(Tickets!G:G,E24) -> 7 | G24: =COUNTIFS(Tickets!G:G,E24,Tickets!Q:Q,"Yes") -> 4 | I24: Omar Yusuf | J24: =COUNTIFS(Tickets!K:K,I24,Tickets!I:I,"Open") -> 1 | K24: =COUNTIFS(Tickets!K:K,I24,Tickets!I:I,"Resolved")+COUNTIFS(Tickets!K:K,I24,Tickets!I:I,"Closed") -> 10
A25: Pending User | B25: =COUNTIF(Tickets!I:I,A25) -> 2 | E25: Printer | F25: =COUNTIF(Tickets!G:G,E25) -> 7 | G25: =COUNTIFS(Tickets!G:G,E25,Tickets!Q:Q,"Yes") -> 3
E26: Mobile Device | F26: =COUNTIF(Tickets!G:G,E26) -> 4 | G26: =COUNTIFS(Tickets!G:G,E26,Tickets!Q:Q,"Yes") -> 1
E27: Other | F27: =COUNTIF(Tickets!G:G,E27) -> 6 | G27: =COUNTIFS(Tickets!G:G,E27,Tickets!Q:Q,"Yes") -> 4

Sheet Tickets
A1: 🎫 HELPDESK TICKETS — FACT TABLE
A2: Primary data table | One row per ticket | Connect to all other tables via Ticket ID
A3: Ticket ID | B3: Created Date | C3: First Response Date | D3: Resolved Date | E3: Closed Date | F3: Priority | G3: Category | H3: Sub-Category | I3: Status | J3: Technician ID | K3: Technician Name | L3: Department | M3: Customer Name | N3: SLA Target (hrs) | O3: Response Time (hrs) | P3: Resolution Time (hrs) | Q3: SLA Breached | R3: Reopen Count | S3: Satisfaction Score | T3: Notes
A4: TKT-0001 | B4: 45652 | C4: 45652 | F4: P3 - Medium | G4: Other | H4: Training Request | I4: Pending User | J4: T005 | K4: Omar Yusuf | L4: IT | M4: Rashed Khalil | N4: 24 | O4: 20.72 | Q4: No | R4: 0
A5: TKT-0002 | B5: 45729 | C5: 45729 | F5: P3 - Medium | G5: Software | H5: Application Error | I5: Open | J5: T004 | K5: Fatima Al-Ali | L5: Finance | M5: Noura Hamdan | N5: 24 | O5: 1.49 | Q5: No | R5: 0
A6: TKT-0003 | B6: 45710 | C6: 45710 | D6: 45710 | F6: P3 - Medium | G6: Access & Security | H6: Password Reset | I6: Resolved | J6: T002 | K6: Sara Mohammed | L6: Legal | M6: Noof Al-Thani | N6: 24 | O6: 18.95 | P6: 21.39 | Q6: No | R6: 0 | S6: 3
A7: TKT-0004 | B7: 45703 | C7: 45703 | F7: P2 - High | G7: Hardware | H7: Laptop Issue | I7: Pending User | J7: T002 | K7: Sara Mohammed | L7: Sales | M7: Tariq Nasser | N7: 8 | O7: 5.8 | Q7: No | R7: 0
A8: TKT-0005 | B8: 45661 | C8: 45663 | D8: 45667 | E8: 45667 | F8: P4 - Low | G8: Network | H8: VPN Issue | I8: Closed | J8: T005 | K8: Omar Yusuf | L8: Executive | M8: Dana Al-Suwaidi | N8: 72 | O8: 49.57 | P8: 149.29 | Q8: No | R8: 0 | S8: 5
A9: TKT-0006 | B9: 45731 | C9: 45733 | D9: 45734 | F9: P4 - Low | G9: Printer | H9: Toner/Ink | I9: Resolved | J9: T002 | K9: Sara Mohammed | L9: Sales | M9: Yousef Al-Mansoori | N9: 72 | O9: 64.96 | P9: 88.97 | Q9: No | R9: 0 | S9: 4
A10: TKT-0007 | B10: 45725 | C10: 45725 | D10: 45725 | F10: P2 - High | G10: Network | H10: VPN Issue | I10: Resolved | J10: T005 | K10: Omar Yusuf | L10: Marketing | M10: Hamad Al-Kuwari | N10: 8 | O10: 2.21 | P10: 8.48 | Q10: No | R10: 0 | S10: 5
A11: TKT-0008 | B11: 45659 | C11: 45659 | F11: P3 - Medium | G11: Network | H11: Switch/Router | I11: In Progress | J11: T004 | K11: Fatima Al-Ali | L11: Sales | M11: Dana Al-Suwaidi | N11: 24 | O11: 21.37 | Q11: No | R11: 0
A12: TKT-0009 | B12: 45647 | C12: 45647 | F12: P3 - Medium | G12: Hardware | H12: Desktop Issue | I12: Open | J12: T002 | K12: Sara Mohammed | L12: Operations | M12: Yousef Al-Mansoori | N12: 24 | O12: 16.24 | Q12: No | R12: 0
A13: TKT-0010 | B13: 45701 | C13: 45702 | F13: P3 - Medium | G13: Hardware | H13: Laptop Issue | I13: Reopened | J13: T005 | K13: Omar Yusuf | L13: Legal | M13: Yousef Al-Mansoori | N13: 24 | O13: 34.19 | Q13: Yes | R13: 1
A14: TKT-0011 | B14: 45694 | C14: 45694 | D14: 45694 | F14: P2 - High | G14: Email & Communication | H14: Outlook Error | I14: Resolved | J14: T003 | K14: Khalid Hassan | L14: Sales | M14: Mona Salem | N14: 8 | O14: 10.63 | P14: 20.7 | Q14: Yes | R14: 0 | S14: 3
A15: TKT-0012 | B15: 45669 | C15: 45669 | D15: 45669 | E15: 45670 | F15: P1 - Critical | G15: Network | H15: Slow Connection | I15: Closed | J15: T004 | K15: Fatima Al-Ali | L15: Sales | M15: Lolwa Hassan | N15: 4 | O15: 5.29 | P15: 10.87 | Q15: Yes | R15: 0 | S15: 4
A16: TKT-0013 | B16: 45668 | C16: 45668 | F16: P3 - Medium | G16: Printer | H16: Driver Issue | I16: In Progress | J16: T005 | K16: Omar Yusuf | L16: Executive | M16: Rashed Khalil | N16: 24 | O16: 2.87 | Q16: No | R16: 1
A17: TKT-0014 | B17: 45670 | C17: 45670 | F17: P2 - High | G17: Other | H17: Feedback | I17: In Progress | J17: T004 | K17: Fatima Al-Ali | L17: Legal | M17: Rashed Khalil | N17: 8 | O17: 9.46 | Q17: Yes | R17: 2
A18: TKT-0015 | B18: 45657 | C18: 45659 | D18: 45660 | E18: 45660 | F18: P4 - Low | G18: Network | H18: VPN Issue | I18: Closed | J18: T001 | K18: Ahmed Al-Rashid | L18: Sales | M18: Yousef Al-Mansoori | N18: 72 | O18: 53.75 | P18: 80.89 | Q18: No | R18: 0 | S18: 3
A19: TKT-0016 | B19: 45656 | C19: 45656 | D19: 45656 | E19: 45656 | F19: P2 - High | G19: Hardware | H19: Laptop Issue | I19: Closed | J19: T005 | K19: Omar Yusuf | L19: Finance | M19: Lolwa Hassan | N19: 8 | O19: 7.35 | P19: 13.4 | Q19: No | R19: 0 | S19: 5
A20: TKT-0017 | B20: 45653 | C20: 45653 | D20: 45653 | E20: 45653 | F20: P2 - High | G20: Hardware | H20: Keyboard/Mouse | I20: Closed | J20: T005 | K20: Omar Yusuf | L20: Legal | M20: Sultan Al-Meer | N20: 8 | O20: 6.96 | P20: 17.96 | Q20: No | R20: 0 | S20: 5
A21: TKT-0018 | B21: 45650 | C21: 45653 | F21: P4 - Low | G21: Hardware | H21: Monitor | I21: Open | J21: T001 | K21: Ahmed Al-Rashid | L21: Executive | M21: Dana Al-Suwaidi | N21: 72 | O21: 95.56 | Q21: Yes | R21: 0
A22: TKT-0019 | B22: 45684 | C22: 45687 | D22: 45688 | E22: 45688 | F22: P4 - Low | G22: Mobile Device | H22: App Install | I22: Closed | J22: T004 | K22: Fatima Al-Ali | L22: IT | M22: Tariq Nasser | N22: 72 | O22: 84.35 | P22: 97.97 | Q22: Yes | R22: 1 | S22: 5
A23: TKT-0020 | B23: 45665 | C23: 45666 | D23: 45667 | E23: 45668 | F23: P3 - Medium | G23: Printer | H23: Print Queue Stuck | I23: Closed | J23: T003 | K23: Khalid Hassan | L23: Finance | M23: Rashed Khalil | N23: 24 | O23: 33.07 | P23: 58.45 | Q23: Yes | R23: 0 | S23: 5
A24: TKT-0021 | B24: 45695 | C24: 45695 | D24: 45696 | E24: 45696 | F24: P3 - Medium | G24: Software | H24: Installation | I24: Closed | J24: T003 | K24: Khalid Hassan | L24: Marketing | M24: Tariq Nasser | N24: 24 | O24: 0.54 | P24: 30.88 | Q24: No | R24: 0 | S24: 3
A25: TKT-0022 | B25: 45734 | C25: 45734 | D25: 45734 | E25: 45734 | F25: P1 - Critical | G25: Email & Communication | H25: Teams Issue | I25: Closed | J25: T004 | K25: Fatima Al-Ali | L25: IT | M25: Mona Salem | N25: 4 | O25: 2.55 | P25: 10.49 | Q25: No | R25: 0 | S25: 3
A26: TKT-0023 | B26: 45715 | C26: 45719 | D26: 45720 | F26: P4 - Low | G26: Access & Security | H26: New User Setup | I26: Resolved | J26: T001 | K26: Ahmed Al-Rashid | L26: Executive | M26: Noof Al-Thani | N26: 72 | O26: 105.04 | P26: 134.84 | Q26: Yes | R26: 0 | S26: 3
A27: TKT-0024 | B27: 45699 | C27: 45700 | F27: P3 - Medium | G27: Network | H27: No Internet | I27: Open | J27: T003 | K27: Khalid Hassan | L27: Marketing | M27: Yousef Al-Mansoori | N27: 24 | O27: 29.51 | Q27: Yes | R27: 0
A28: TKT-0025 | B28: 45654 | C28: 45654 | D28: 45654 | E28: 45655 | F28: P3 - Medium | G28: Access & Security | H28: Account Locked | I28: Closed | J28: T001 | K28: Ahmed Al-Rashid | L28: Finance | M28: Rashed Khalil | N28: 24 | O28: 10.86 | P28: 12.15 | Q28: No | R28: 0 | S28: 3
A29: TKT-0026 | B29: 45716 | C29: 45717 | F29: P3 - Medium | G29: Email & Communication | H29: Teams Issue | I29: Reopened | J29: T001 | K29: Ahmed Al-Rashid | L29: HR | M29: Tariq Nasser | N29: 24 | O29: 25.02 | Q29: Yes | R29: 0
A30: TKT-0027 | B30: 45655 | C30: 45655 | D30: 45655 | E30: 45655 | F30: P2 - High | G30: Network | H30: No Internet | I30: Closed | J30: T005 | K30: Omar Yusuf | L30: IT | M30: Yousef Al-Mansoori | N30: 8 | O30: 11.73 | P30: 15.04 | Q30: Yes | R30: 0 | S30: 3
A31: TKT-0028 | B31: 45718 | C31: 45719 | F31: P3 - Medium | G31: Printer | H31: Toner/Ink | I31: In Progress | J31: T004 | K31: Fatima Al-Ali | L31: Executive | M31: Yousef Al-Mansoori | N31: 24 | O31: 31.52 | Q31: Yes | R31: 0
A32: TKT-0029 | B32: 45666 | C32: 45666 | D32: 45666 | F32: P2 - High | G32: Access & Security | H32: New User Setup | I32: Resolved | J32: T003 | K32: Khalid Hassan | L32: HR | M32: Hamad Al-Kuwari | N32: 8 | O32: 4.73 | P32: 6.23 | Q32: No | R32: 0 | S32: 3
A33: TKT-0030 | B33: 45653 | C33: 45655 | D33: 45658 | E33: 45659 | F33: P4 - Low | G33: Access & Security | H33: Password Reset | I33: Closed | J33: T003 | K33: Khalid Hassan | L33: Marketing | M33: Noof Al-Thani | N33: 72 | O33: 61.2 | P33: 139.11 | Q33: No | R33: 0 | S33: 5
A34: TKT-0031 | B34: 45684 | C34: 45685 | F34: P3 - Medium | G34: Printer | H34: Paper Jam | I34: In Progress | J34: T002 | K34: Sara Mohammed | L34: Finance | M34: Rashed Khalil | N34: 24 | O34: 28.7 | Q34: Yes | R34: 0
A35: TKT-0032 | B35: 45691 | C35: 45692 | F35: P3 - Medium | G35: Software | H35: Update Failure | I35: Open | J35: T001 | K35: Ahmed Al-Rashid | L35: IT | M35: Hessa Al-Zaabi | N35: 24 | O35: 31.38 | Q35: Yes | R35: 0
A36: TKT-0033 | B36: 45650 | C36: 45651 | D36: 45651 | F36: P3 - Medium | G36: Email & Communication | H36: Teams Issue | I36: Resolved | J36: T002 | K36: Sara Mohammed | L36: IT | M36: Majed Al-Farsi | N36: 24 | O36: 33.4 | P36: 37.74 | Q36: Yes | R36: 0 | S36: 5
A37: TKT-0034 | B37: 45651 | C37: 45651 | D37: 45651 | E37: 45651 | F37: P1 - Critical | G37: Network | H37: Switch/Router | I37: Closed | J37: T005 | K37: Omar Yusuf | L37: Sales | M37: Noof Al-Thani | N37: 4 | O37: 4.08 | P37: 7.41 | Q37: Yes | R37: 0 | S37: 5
A38: TKT-0035 | B38: 45675 | C38: 45675 | D38: 45675 | E38: 45676 | F38: P2 - High | G38: Network | H38: Switch/Router | I38: Closed | J38: T001 | K38: Ahmed Al-Rashid | L38: Marketing | M38: Badr Mohammed | N38: 8 | O38: 9.84 | P38: 13 | Q38: Yes | R38: 0 | S38: 5
A39: TKT-0036 | B39: 45711 | C39: 45711 | D39: 45711 | E39: 45712 | F39: P3 - Medium | G39: Mobile Device | H39: Data Sync | I39: Closed | J39: T001 | K39: Ahmed Al-Rashid | L39: Marketing | M39: Lolwa Hassan | N39: 24 | O39: 7.17 | P39: 16.01 | Q39: No | R39: 0 | S39: 3
A40: TKT-0037 | B40: 45718 | C40: 45718 | D40: 45719 | E40: 45720 | F40: P3 - Medium | G40: Email & Communication | H40: Outlook Error | I40: Closed | J40: T001 | K40: Ahmed Al-Rashid | L40: Finance | M40: Noura Hamdan | N40: 24 | O40: 21.56 | P40: 44.91 | Q40: No | R40: 0 | S40: 3
...

Sheet Technicians
A1: 👨‍💻 TECHNICIANS — DIMENSION TABLE
A2: Technician master data | Relates to Tickets via Technician ID
A3: Technician ID | B3: Full Name | C3: Email | D3: Specialization | E3: Shift | F3: Team | G3: Max Ticket Capacity | H3: Current Open Tickets | I3: Avg Resolution Time (hrs) | J3: Satisfaction Avg | K3: Status
A4: T001 | B4: Ahmed Al-Rashid | C4: ahmed@helpdesk.qa | D4: Hardware & Network | E4: Morning | F4: Tier 1 | G4: 15 | H4: =COUNTIFS(Tickets!J:J,A4,Tickets!I:I,"Open")+COUNTIFS(Tickets!J:J,A4,Tickets!I:I,"In Progress") -> 4 | I4: =IFERROR(AVERAGEIFS(Tickets!P:P,Tickets!J:J,A4,Tickets!P:P,"<>"),0) -> 50.3 | J4: =IFERROR(AVERAGEIFS(Tickets!S:S,Tickets!J:J,A4,Tickets!S:S,"<>"),0) -> 3.3333333 | K4: Active
A5: T002 | B5: Sara Mohammed | C5: sara@helpdesk.qa | D5: Software & OS | E5: Morning | F5: Tier 1 | G5: 15 | H5: =COUNTIFS(Tickets!J:J,A5,Tickets!I:I,"Open")+COUNTIFS(Tickets!J:J,A5,Tickets!I:I,"In Progress") -> 5 | I5: =IFERROR(AVERAGEIFS(Tickets!P:P,Tickets!J:J,A5,Tickets!P:P,"<>"),0) -> 43.256 | J5: =IFERROR(AVERAGEIFS(Tickets!S:S,Tickets!J:J,A5,Tickets!S:S,"<>"),0) -> 4 | K5: Active
A6: T003 | B6: Khalid Hassan | C6: khalid@helpdesk.qa | D6: Security & Access | E6: Evening | F6: Tier 2 | G6: 10 | H6: =COUNTIFS(Tickets!J:J,A6,Tickets!I:I,"Open")+COUNTIFS(Tickets!J:J,A6,Tickets!I:I,"In Progress") -> 3 | I6: =IFERROR(AVERAGEIFS(Tickets!P:P,Tickets!J:J,A6,Tickets!P:P,"<>"),0) -> 50.578 | J6: =IFERROR(AVERAGEIFS(Tickets!S:S,Tickets!J:J,A6,Tickets!S:S,"<>"),0) -> 3.9 | K6: Active
A7: T004 | B7: Fatima Al-Ali | C7: fatima@helpdesk.qa | D7: Applications | E7: Evening | F7: Tier 2 | G7: 10 | H7: =COUNTIFS(Tickets!J:J,A7,Tickets!I:I,"Open")+COUNTIFS(Tickets!J:J,A7,Tickets!I:I,"In Progress") -> 4 | I7: =IFERROR(AVERAGEIFS(Tickets!P:P,Tickets!J:J,A7,Tickets!P:P,"<>"),0) -> 33.386 | J7: =IFERROR(AVERAGEIFS(Tickets!S:S,Tickets!J:J,A7,Tickets!S:S,"<>"),0) -> 3.8 | K7: Active
A8: T005 | B8: Omar Yusuf | C8: omar@helpdesk.qa | D8: Network & Infrastructure | E8: Morning | F8: Tier 3 | G8: 8 | H8: =COUNTIFS(Tickets!J:J,A8,Tickets!I:I,"Open")+COUNTIFS(Tickets!J:J,A8,Tickets!I:I,"In Progress") -> 3 | I8: =IFERROR(AVERAGEIFS(Tickets!P:P,Tickets!J:J,A8,Tickets!P:P,"<>"),0) -> 40.143 | J8: =IFERROR(AVERAGEIFS(Tickets!S:S,Tickets!J:J,A8,Tickets!S:S,"<>"),0) -> 4 | K8: Active

Sheet SLA Rules
A1: ⏱️ SLA RULES & TARGETS
A2: Define SLA targets by priority | These drive all SLA compliance calculations
A3: Priority | B3: SLA Tier | C3: First Response (hrs) | D3: Resolution Target (hrs) | E3: Escalation Threshold (hrs) | F3: Business Hours Only | G3: Penalty (QAR/hr breach) | H3: Description | I3: Examples
A4: P1 - Critical | B4: Gold | C4: 1 | D4: 4 | E4: 2 | F4: No | G4: 500 | H4: Total system outage affecting all users. Immediate response required 24/7. | I4: Server down, network outage, security breach, complete email failure
A5: P2 - High | B5: Silver | C5: 2 | D5: 8 | E5: 4 | F5: No | G5: 200 | H5: Major functionality impacted. Multiple users affected. Same-day resolution expected. | I5: Application crash, VPN failure, multiple users locked out, key system unavailable
A6: P3 - Medium | B6: Bronze | C6: 4 | D6: 24 | E6: 8 | F6: Yes | G6: 50 | H6: Single user affected or minor impact. Next business day acceptable. | I6: Single app error, password reset, software install, printer issue
A7: P4 - Low | B7: Standard | C7: 8 | D7: 72 | E7: 24 | F7: Yes | G7: 0 | H7: General request, no impact on productivity. Best effort. | I7: Training requests, general queries, new software evaluation, documentation

Sheet Categories
A1: 🗂️ CATEGORIES — DIMENSION TABLE
A2: Category hierarchy and routing rules | Use for ticket classification
A3: Category ID | B3: Category | C3: Sub-Category | D3: Default Priority | E3: Assigned Team | F3: Avg Resolution (hrs) | G3: Ticket Count | H3: % of Total | I3: Most Common Issue
A4: CAT-001 | B4: Hardware | C4: Laptop Issue | D4: P3 - Medium | E4: Tier 1 | G4: =COUNTIFS(Tickets!G:G,B4,Tickets!H:H,C4) -> 4 | H4: =IFERROR(G4/COUNTA(Tickets!A4:A500),0) -> 0.066666667
A5: CAT-002 | B5: Hardware | C5: Desktop Issue | D5: P3 - Medium | E5: Tier 1 | G5: =COUNTIFS(Tickets!G:G,B5,Tickets!H:H,C5) -> 1 | H5: =IFERROR(G5/COUNTA(Tickets!A4:A500),0) -> 0.016666667
A6: CAT-003 | B6: Hardware | C6: Monitor | D6: P3 - Medium | E6: Tier 1 | G6: =COUNTIFS(Tickets!G:G,B6,Tickets!H:H,C6) -> 1 | H6: =IFERROR(G6/COUNTA(Tickets!A4:A500),0) -> 0.016666667
A7: CAT-004 | B7: Hardware | C7: Keyboard/Mouse | D7: P3 - Medium | E7: Tier 1 | G7: =COUNTIFS(Tickets!G:G,B7,Tickets!H:H,C7) -> 1 | H7: =IFERROR(G7/COUNTA(Tickets!A4:A500),0) -> 0.016666667
A8: CAT-005 | B8: Hardware | C8: RAM/Storage | D8: P3 - Medium | E8: Tier 1 | G8: =COUNTIFS(Tickets!G:G,B8,Tickets!H:H,C8) -> 1 | H8: =IFERROR(G8/COUNTA(Tickets!A4:A500),0) -> 0.016666667
A9: CAT-006 | B9: Software | C9: OS Crash | D9: P3 - Medium | E9: Tier 2 | G9: =COUNTIFS(Tickets!G:G,B9,Tickets!H:H,C9) -> 0 | H9: =IFERROR(G9/COUNTA(Tickets!A4:A500),0) -> 0
A10: CAT-007 | B10: Software | C10: Application Error | D10: P3 - Medium | E10: Tier 2 | G10: =COUNTIFS(Tickets!G:G,B10,Tickets!H:H,C10) -> 3 | H10: =IFERROR(G10/COUNTA(Tickets!A4:A500),0) -> 0.05
A11: CAT-008 | B11: Software | C11: Installation | D11: P3 - Medium | E11: Tier 2 | G11: =COUNTIFS(Tickets!G:G,B11,Tickets!H:H,C11) -> 1 | H11: =IFERROR(G11/COUNTA(Tickets!A4:A500),0) -> 0.016666667
A12: CAT-009 | B12: Software | C12: License Issue | D12: P3 - Medium | E12: Tier 2 | G12: =COUNTIFS(Tickets!G:G,B12,Tickets!H:H,C12) -> 0 | H12: =IFERROR(G12/COUNTA(Tickets!A4:A500),0) -> 0
A13: CAT-010 | B13: Software | C13: Update Failure | D13: P3 - Medium | E13: Tier 2 | G13: =COUNTIFS(Tickets!G:G,B13,Tickets!H:H,C13) -> 2 | H13: =IFERROR(G13/COUNTA(Tickets!A4:A500),0) -> 0.033333333
A14: CAT-011 | B14: Network | C14: No Internet | D14: P1 - Critical | E14: Tier 2 | G14: =COUNTIFS(Tickets!G:G,B14,Tickets!H:H,C14) -> 4 | H14: =IFERROR(G14/COUNTA(Tickets!A4:A500),0) -> 0.066666667
A15: CAT-012 | B15: Network | C15: Slow Connection | D15: P2 - High | E15: Tier 2 | G15: =COUNTIFS(Tickets!G:G,B15,Tickets!H:H,C15) -> 1 | H15: =IFERROR(G15/COUNTA(Tickets!A4:A500),0) -> 0.016666667
A16: CAT-013 | B16: Network | C16: VPN Issue | D16: P2 - High | E16: Tier 2 | G16: =COUNTIFS(Tickets!G:G,B16,Tickets!H:H,C16) -> 3 | H16: =IFERROR(G16/COUNTA(Tickets!A4:A500),0) -> 0.05
A17: CAT-014 | B17: Network | C17: Wi-Fi Drop | D17: P2 - High | E17: Tier 2 | G17: =COUNTIFS(Tickets!G:G,B17,Tickets!H:H,C17) -> 1 | H17: =IFERROR(G17/COUNTA(Tickets!A4:A500),0) -> 0.016666667
A18: CAT-015 | B18: Network | C18: Switch/Router | D18: P2 - High | E18: Tier 2 | G18: =COUNTIFS(Tickets!G:G,B18,Tickets!H:H,C18) -> 5 | H18: =IFERROR(G18/COUNTA(Tickets!A4:A500),0) -> 0.083333333
A19: CAT-016 | B19: Access & Security | C19: Password Reset | D19: P2 - High | E19: Tier 2 | G19: =COUNTIFS(Tickets!G:G,B19,Tickets!H:H,C19) -> 2 | H19: =IFERROR(G19/COUNTA(Tickets!A4:A500),0) -> 0.033333333
A20: CAT-017 | B20: Access & Security | C20: Account Locked | D20: P2 - High | E20: Tier 2 | G20: =COUNTIFS(Tickets!G:G,B20,Tickets!H:H,C20) -> 2 | H20: =IFERROR(G20/COUNTA(Tickets!A4:A500),0) -> 0.033333333
A21: CAT-018 | B21: Access & Security | C21: New User Setup | D21: P2 - High | E21: Tier 2 | G21: =COUNTIFS(Tickets!G:G,B21,Tickets!H:H,C21) -> 3 | H21: =IFERROR(G21/COUNTA(Tickets!A4:A500),0) -> 0.05
A22: CAT-019 | B22: Access & Security | C22: Permission Change | D22: P2 - High | E22: Tier 2 | G22: =COUNTIFS(Tickets!G:G,B22,Tickets!H:H,C22) -> 1 | H22: =IFERROR(G22/COUNTA(Tickets!A4:A500),0) -> 0.016666667
A23: CAT-020 | B23: Access & Security | C23: MFA Issue | D23: P2 - High | E23: Tier 2 | G23: =COUNTIFS(Tickets!G:G,B23,Tickets!H:H,C23) -> 0 | H23: =IFERROR(G23/COUNTA(Tickets!A4:A500),0) -> 0
A24: CAT-021 | B24: Email & Communication | C24: Email Not Sending | D24: P3 - Medium | E24: Tier 2 | G24: =COUNTIFS(Tickets!G:G,B24,Tickets!H:H,C24) -> 0 | H24: =IFERROR(G24/COUNTA(Tickets!A4:A500),0) -> 0
A25: CAT-022 | B25: Email & Communication | C25: Outlook Error | D25: P3 - Medium | E25: Tier 2 | G25: =COUNTIFS(Tickets!G:G,B25,Tickets!H:H,C25) -> 2 | H25: =IFERROR(G25/COUNTA(Tickets!A4:A500),0) -> 0.033333333
A26: CAT-023 | B26: Email & Communication | C26: Teams Issue | D26: P3 - Medium | E26: Tier 2 | G26: =COUNTIFS(Tickets!G:G,B26,Tickets!H:H,C26) -> 3 | H26: =IFERROR(G26/COUNTA(Tickets!A4:A500),0) -> 0.05
A27: CAT-024 | B27: Email & Communication | C27: Calendar Sync | D27: P3 - Medium | E27: Tier 2 | G27: =COUNTIFS(Tickets!G:G,B27,Tickets!H:H,C27) -> 2 | H27: =IFERROR(G27/COUNTA(Tickets!A4:A500),0) -> 0.033333333
A28: CAT-025 | B28: Email & Communication | C28: Distribution List | D28: P3 - Medium | E28: Tier 2 | G28: =COUNTIFS(Tickets!G:G,B28,Tickets!H:H,C28) -> 0 | H28: =IFERROR(G28/COUNTA(Tickets!A4:A500),0) -> 0
A29: CAT-026 | B29: Printer | C29: Print Queue Stuck | D29: P3 - Medium | E29: Tier 1 | G29: =COUNTIFS(Tickets!G:G,B29,Tickets!H:H,C29) -> 2 | H29: =IFERROR(G29/COUNTA(Tickets!A4:A500),0) -> 0.033333333
A30: CAT-027 | B30: Printer | C30: Offline Printer | D30: P3 - Medium | E30: Tier 1 | G30: =COUNTIFS(Tickets!G:G,B30,Tickets!H:H,C30) -> 0 | H30: =IFERROR(G30/COUNTA(Tickets!A4:A500),0) -> 0
A31: CAT-028 | B31: Printer | C31: Driver Issue | D31: P3 - Medium | E31: Tier 1 | G31: =COUNTIFS(Tickets!G:G,B31,Tickets!H:H,C31) -> 1 | H31: =IFERROR(G31/COUNTA(Tickets!A4:A500),0) -> 0.016666667
A32: CAT-029 | B32: Printer | C32: Paper Jam | D32: P3 - Medium | E32: Tier 1 | G32: =COUNTIFS(Tickets!G:G,B32,Tickets!H:H,C32) -> 2 | H32: =IFERROR(G32/COUNTA(Tickets!A4:A500),0) -> 0.033333333
A33: CAT-030 | B33: Printer | C33: Toner/Ink | D33: P3 - Medium | E33: Tier 1 | G33: =COUNTIFS(Tickets!G:G,B33,Tickets!H:H,C33) -> 2 | H33: =IFERROR(G33/COUNTA(Tickets!A4:A500),0) -> 0.033333333
A34: CAT-031 | B34: Mobile Device | C34: Phone Setup | D34: P3 - Medium | E34: Tier 1 | G34: =COUNTIFS(Tickets!G:G,B34,Tickets!H:H,C34) -> 0 | H34: =IFERROR(G34/COUNTA(Tickets!A4:A500),0) -> 0
A35: CAT-032 | B35: Mobile Device | C35: MDM Enrollment | D35: P3 - Medium | E35: Tier 1 | G35: =COUNTIFS(Tickets!G:G,B35,Tickets!H:H,C35) -> 0 | H35: =IFERROR(G35/COUNTA(Tickets!A4:A500),0) -> 0
A36: CAT-033 | B36: Mobile Device | C36: App Install | D36: P3 - Medium | E36: Tier 1 | G36: =COUNTIFS(Tickets!G:G,B36,Tickets!H:H,C36) -> 2 | H36: =IFERROR(G36/COUNTA(Tickets!A4:A500),0) -> 0.033333333
A37: CAT-034 | B37: Mobile Device | C37: Data Sync | D37: P3 - Medium | E37: Tier 1 | G37: =COUNTIFS(Tickets!G:G,B37,Tickets!H:H,C37) -> 1 | H37: =IFERROR(G37/COUNTA(Tickets!A4:A500),0) -> 0.016666667
A38: CAT-035 | B38: Mobile Device | C38: Lost Device | D38: P3 - Medium | E38: Tier 1 | G38: =COUNTIFS(Tickets!G:G,B38,Tickets!H:H,C38) -> 1 | H38: =IFERROR(G38/COUNTA(Tickets!A4:A500),0) -> 0.016666667
A39: CAT-036 | B39: Other | C39: General Query | D39: P3 - Medium | E39: Tier 2 | G39: =COUNTIFS(Tickets!G:G,B39,Tickets!H:H,C39) -> 0 | H39: =IFERROR(G39/COUNTA(Tickets!A4:A500),0) -> 0
A40: CAT-037 | B40: Other | C40: Training Request | D40: P3 - Medium | E40: Tier 2 | G40: =COUNTIFS(Tickets!G:G,B40,Tickets!H:H,C40) -> 3 | H40: =IFERROR(G40/COUNTA(Tickets!A4:A500),0) -> 0.05
...

Sheet KPI Calculations
A1: 📐 KPI CALCULATIONS — EXCEL FORMULAS
A2: All KPI formulas with explanations | This sheet feeds the Dashboard
A3: KPI Name | B3: Calculated Value | C3: Formula Used | D3: Notes & Explanation
A4: 📊 SECTION 1: TICKET VOLUME KPIs
A5: Total Tickets | B5: =COUNTA(Tickets!A4:A500)-COUNTBLANK(Tickets!A4:A500) -> -377 | C5: =COUNTA(Tickets!A4:A500)-COUNTBLANK(Tickets!A4:A500) -> -377 | D5: Counts all non-blank Ticket IDs. Adjust range as data grows.
A6: Open Tickets | B6: =COUNTIF(Tickets!I:I,"Open") -> 7 | C6: =COUNTIF(Tickets!I:I,"Open") -> 7 | D6: All tickets with Status = Open. These need immediate attention.
A7: In Progress Tickets | B7: =COUNTIF(Tickets!I:I,"In Progress") -> 12 | C7: =COUNTIF(Tickets!I:I,"In Progress") -> 12 | D7: Tickets actively being worked on by a technician.
A8: Resolved Tickets | B8: =COUNTIF(Tickets!I:I,"Resolved") -> 15 | C8: =COUNTIF(Tickets!I:I,"Resolved") -> 15 | D8: Tickets marked Resolved but not yet formally Closed by customer.
A9: Closed Tickets | B9: =COUNTIF(Tickets!I:I,"Closed") -> 21 | C9: =COUNTIF(Tickets!I:I,"Closed") -> 21 | D9: Fully closed tickets with customer sign-off.
A10: Reopened Tickets | B10: =COUNTIF(Tickets!I:I,"Reopened") -> 3 | C10: =COUNTIF(Tickets!I:I,"Reopened") -> 3 | D10: Tickets reopened after resolution — indicator of quality issues.
A11: Pending User Tickets | B11: =COUNTIF(Tickets!I:I,"Pending User") -> 2 | C11: =COUNTIF(Tickets!I:I,"Pending User") -> 2 | D11: Awaiting response from end user. Should not count against SLA.
A12: Ticket Backlog | B12: =COUNTIF(Tickets!I:I,"Open")+COUNTIF(Tickets!I:I,"In Progress") -> 19 | C12: =COUNTIF(Tickets!I:I,"Open")+COUNTIF(Tickets!I:I,"In Progress") -> 19 | D12: Total unresolved tickets = Open + In Progress. Key daily metric.
A13: Backlog Rate % | B13: =IFERROR((COUNTIF(Tickets!I:I,"Open")+COUNTIF(Tickets!I:I,"In Progress"))/MAX(COUNTA(Tickets!A4:A500)-COUNTBLANK(Tickets!A4:A500),1),0) -> 19 | C13: =IFERROR((COUNTIF(Tickets!I:I,"Open")+COUNTIF(Tickets!I:I,"In Progress"))/MAX(COUNTA(Tickets!A4:A500)-COUNTBLANK(Tickets!A4:A500),1),0) -> 19 | D13: Backlog / Total Tickets. >20% signals capacity issues.
A14: Reopen Rate % | B14: =IFERROR(COUNTIF(Tickets!I:I,"Reopened")/MAX(COUNTA(Tickets!A4:A500)-COUNTBLANK(Tickets!A4:A500),1),0) -> 3 | C14: =IFERROR(COUNTIF(Tickets!I:I,"Reopened")/MAX(COUNTA(Tickets!A4:A500)-COUNTBLANK(Tickets!A4:A500),1),0) -> 3 | D14: % tickets reopened. Target: <5%. High rate = poor first-contact resolution.
A16: ⏱️ SECTION 2: SLA & RESPONSE TIME KPIs
A17: Avg Response Time (hrs) | B17: =IFERROR(AVERAGEIF(Tickets!O:O,"<>",Tickets!O:O),0) -> 25.1565 | C17: =IFERROR(AVERAGEIF(Tickets!O:O,"<>",Tickets!O:O),0) -> 25.1565 | D17: Average first response time across all tickets. Include only non-blank values.
A18: Avg Resolution Time (hrs) | B18: =IFERROR(AVERAGEIF(Tickets!P:P,"<>",Tickets!P:P),0) -> 44.228333 | C18: =IFERROR(AVERAGEIF(Tickets!P:P,"<>",Tickets!P:P),0) -> 44.228333 | D18: Average hours to resolve. Exclude open/pending tickets from average.
A19: SLA Breach Count | B19: =COUNTIF(Tickets!Q:Q,"Yes") -> 30 | C19: =COUNTIF(Tickets!Q:Q,"Yes") -> 30 | D19: Total tickets where response time exceeded SLA target for that priority.
A20: SLA Compliance % | B20: =IFERROR(COUNTIF(Tickets!Q:Q,"No")/MAX(COUNTA(Tickets!A4:A500)-COUNTBLANK(Tickets!A4:A500),1),0) -> 30 | C20: =IFERROR(COUNTIF(Tickets!Q:Q,"No")/MAX(COUNTA(Tickets!A4:A500)-COUNTBLANK(Tickets!A4:A500),1),0) -> 30 | D20: % tickets resolved within SLA. Target: ≥95% for P1, ≥90% overall.
A21: P1 SLA Compliance % | B21: =IFERROR(COUNTIFS(Tickets!F:F,"P1 - Critical",Tickets!Q:Q,"No")/MAX(COUNTIF(Tickets!F:F,"P1 - Critical"),1),0) -> 0.33333333 | C21: =IFERROR(COUNTIFS(Tickets!F:F,"P1 - Critical",Tickets!Q:Q,"No")/MAX(COUNTIF(Tickets!F:F,"P1 - Critical"),1),0) -> 0.33333333 | D21: SLA compliance for critical tickets only. Must be ≥98%.
A22: P2 SLA Compliance % | B22: =IFERROR(COUNTIFS(Tickets!F:F,"P2 - High",Tickets!Q:Q,"No")/MAX(COUNTIF(Tickets!F:F,"P2 - High"),1),0) -> 0.53846154 | C22: =IFERROR(COUNTIFS(Tickets!F:F,"P2 - High",Tickets!Q:Q,"No")/MAX(COUNTIF(Tickets!F:F,"P2 - High"),1),0) -> 0.53846154 | D22: SLA compliance for high priority. Target ≥95%.
A23: P3 SLA Compliance % | B23: =IFERROR(COUNTIFS(Tickets!F:F,"P3 - Medium",Tickets!Q:Q,"No")/MAX(COUNTIF(Tickets!F:F,"P3 - Medium"),1),0) -> 0.46666667 | C23: =IFERROR(COUNTIFS(Tickets!F:F,"P3 - Medium",Tickets!Q:Q,"No")/MAX(COUNTIF(Tickets!F:F,"P3 - Medium"),1),0) -> 0.46666667 | D23: SLA compliance for medium priority. Target ≥90%.
A24: Avg Response P1 (hrs) | B24: =IFERROR(AVERAGEIFS(Tickets!O:O,Tickets!F:F,"P1 - Critical",Tickets!O:O,"<>"),0) -> 3.9866667 | C24: =IFERROR(AVERAGEIFS(Tickets!O:O,Tickets!F:F,"P1 - Critical",Tickets!O:O,"<>"),0) -> 3.9866667 | D24: Average response time for P1 tickets only. Must be <1 hour.
A25: Avg Response P2 (hrs) | B25: =IFERROR(AVERAGEIFS(Tickets!O:O,Tickets!F:F,"P2 - High",Tickets!O:O,"<>"),0) -> 7.5238462 | C25: =IFERROR(AVERAGEIFS(Tickets!O:O,Tickets!F:F,"P2 - High",Tickets!O:O,"<>"),0) -> 7.5238462 | D25: Average response time for P2 tickets only. Target: <2 hours.
A26: Avg Resolution P1 (hrs) | B26: =IFERROR(AVERAGEIFS(Tickets!P:P,Tickets!F:F,"P1 - Critical",Tickets!P:P,"<>"),0) -> 9.13 | C26: =IFERROR(AVERAGEIFS(Tickets!P:P,Tickets!F:F,"P1 - Critical",Tickets!P:P,"<>"),0) -> 9.13 | D26: Average resolution for P1 tickets. Target: <4 hours.
A28: ⭐ SECTION 3: QUALITY & SATISFACTION KPIs
A29: Avg Satisfaction Score | B29: =IFERROR(AVERAGEIF(Tickets!S:S,"<>",Tickets!S:S),0) -> 3.8333333 | C29: =IFERROR(AVERAGEIF(Tickets!S:S,"<>",Tickets!S:S),0) -> 3.8333333 | D29: Average CSAT out of 5. Target ≥4.0. Based on closed/resolved tickets only.
A30: Tickets Rated 5 (Excellent) | B30: =COUNTIF(Tickets!S:S,5) -> 12 | C30: =COUNTIF(Tickets!S:S,5) -> 12 | D30: Count of top-rated tickets. Use for recognition and benchmarking.
A31: Tickets Rated ≤2 (Poor) | B31: =COUNTIF(Tickets!S:S,"<=2") -> 0 | C31: =COUNTIF(Tickets!S:S,"<=2") -> 0 | D31: Count of low satisfaction scores. Review these for escalation patterns.
A32: First Contact Resolution % | B32: =IFERROR(COUNTIFS(Tickets!R:R,0,Tickets!I:I,"Closed")/MAX(COUNTIF(Tickets!I:I,"Closed"),1),0) -> 0.95238095 | C32: =IFERROR(COUNTIFS(Tickets!R:R,0,Tickets!I:I,"Closed")/MAX(COUNTIF(Tickets!I:I,"Closed"),1),0) -> 0.95238095 | D32: % tickets resolved on first contact (Reopen Count = 0). Target ≥80%.
A33: Avg Reopen Count | B33: =IFERROR(AVERAGEIF(Tickets!R:R,"<>",Tickets!R:R),0) -> 0.16666667 | C33: =IFERROR(AVERAGEIF(Tickets!R:R,"<>",Tickets!R:R),0) -> 0.16666667 | D33: Average number of times tickets are reopened. Target: <0.1.
A34: Tickets Open > 7 Days | B34: =COUNTIFS(Tickets!I:I,"Open",Tickets!B:B,"<="&(TODAY()-7)) -> 7 | C34: =COUNTIFS(Tickets!I:I,"Open",Tickets!B:B,"<="&(TODAY()-7)) -> 7 | D34: Aging open tickets older than 7 days. Critical backlog alert.
A35: Tickets Open > 14 Days | B35: =COUNTIFS(Tickets!I:I,"Open",Tickets!B:B,"<="&(TODAY()-14)) -> 7 | C35: =COUNTIFS(Tickets!I:I,"Open",Tickets!B:B,"<="&(TODAY()-14)) -> 7 | D35: Very aged tickets. Needs immediate management escalation.
A36: Tickets Open > 30 Days | B36: =COUNTIFS(Tickets!I:I,"Open",Tickets!B:B,"<="&(TODAY()-30)) -> 7 | C36: =COUNTIFS(Tickets!I:I,"Open",Tickets!B:B,"<="&(TODAY()-30)) -> 7 | D36: Severely aged tickets. Should be near-zero in healthy helpdesks.
A38: 👨‍💻 SECTION 4: TECHNICIAN PERFORMANCE (Parameterised)
A39: ← Change Technician ID in cell B40 to recalculate all technician KPIs
A40: Selected Technician ID: | B40: T001
A41: Technician Name | B41: =IFERROR(xlookup(B40,Technicians!A:A,Technicians!B:B,"Not Found"),"Not Found") -> Not Found | C41: =IFERROR(xlookup(B40,Technicians!A:A,Technicians!B:B,"Not Found"),"Not Found") -> Not Found | D41: Lookup technician name from Technicians table using selected ID.
A42: Tickets Assigned (Total) | B42: =COUNTIF(Tickets!J:J,B40) -> 11 | C42: =COUNTIF(Tickets!J:J,B40) -> 11 | D42: Total tickets ever assigned to this technician.
A43: Open Tickets | B43: =COUNTIFS(Tickets!J:J,B40,Tickets!I:I,"Open") -> 2 | C43: =COUNTIFS(Tickets!J:J,B40,Tickets!I:I,"Open") -> 2 | D43: Current open workload for this technician.
...

Sheet Pivot Summary
A1: 📊 PIVOT SUMMARIES — AGGREGATED ANALYTICS
A2: Pre-built summary tables | Replicate as Pivot Tables in Excel or use COUNTIFS formulas directly
A4: 📦 Tickets by Category | K4: 🎯 Tickets by Priority
A5: Category | B5: Total | C5: Open | D5: In Progress | E5: Resolved | F5: Closed | G5: SLA Breach | H5: Avg Res. (hrs) | K5: Priority | L5: Total | M5: SLA Met | N5: SLA Breached | O5: Compliance % | P5: Avg Response | Q5: Avg Resolution
A6: Hardware | B6: =COUNTIF(Tickets!G:G,A6) -> 8 | C6: =COUNTIFS(Tickets!G:G,A6,Tickets!I:I,"Open") -> 2 | D6: =COUNTIFS(Tickets!G:G,A6,Tickets!I:I,"In Progress") -> 1 | E6: =COUNTIFS(Tickets!G:G,A6,Tickets!I:I,"Resolved") -> 0 | F6: =COUNTIFS(Tickets!G:G,A6,Tickets!I:I,"Closed") -> 3 | G6: =COUNTIFS(Tickets!G:G,A6,Tickets!Q:Q,"Yes") -> 3 | H6: =IFERROR(AVERAGEIFS(Tickets!P:P,Tickets!G:G,A6,Tickets!P:P,"<>"),0) -> 40.626667 | K6: P1 - Critical | L6: =COUNTIF(Tickets!F:F,K6) -> 6 | M6: =COUNTIFS(Tickets!F:F,K6,Tickets!Q:Q,"No") -> 2 | N6: =COUNTIFS(Tickets!F:F,K6,Tickets!Q:Q,"Yes") -> 4 | O6: =IFERROR(M6/MAX(L6,1),0) -> 0.33333333 | P6: =IFERROR(AVERAGEIFS(Tickets!O:O,Tickets!F:F,K6,Tickets!O:O,"<>"),0) -> 3.9866667 | Q6: =IFERROR(AVERAGEIFS(Tickets!P:P,Tickets!F:F,K6,Tickets!P:P,"<>"),0) -> 9.13
A7: Software | B7: =COUNTIF(Tickets!G:G,A7) -> 6 | C7: =COUNTIFS(Tickets!G:G,A7,Tickets!I:I,"Open") -> 2 | D7: =COUNTIFS(Tickets!G:G,A7,Tickets!I:I,"In Progress") -> 1 | E7: =COUNTIFS(Tickets!G:G,A7,Tickets!I:I,"Resolved") -> 0 | F7: =COUNTIFS(Tickets!G:G,A7,Tickets!I:I,"Closed") -> 3 | G7: =COUNTIFS(Tickets!G:G,A7,Tickets!Q:Q,"Yes") -> 4 | H7: =IFERROR(AVERAGEIFS(Tickets!P:P,Tickets!G:G,A7,Tickets!P:P,"<>"),0) -> 44.256667 | K7: P2 - High | L7: =COUNTIF(Tickets!F:F,K7) -> 13 | M7: =COUNTIFS(Tickets!F:F,K7,Tickets!Q:Q,"No") -> 7 | N7: =COUNTIFS(Tickets!F:F,K7,Tickets!Q:Q,"Yes") -> 6 | O7: =IFERROR(M7/MAX(L7,1),0) -> 0.53846154 | P7: =IFERROR(AVERAGEIFS(Tickets!O:O,Tickets!F:F,K7,Tickets!O:O,"<>"),0) -> 7.5238462 | Q7: =IFERROR(AVERAGEIFS(Tickets!P:P,Tickets!F:F,K7,Tickets!P:P,"<>"),0) -> 13.854
A8: Network | B8: =COUNTIF(Tickets!G:G,A8) -> 14 | C8: =COUNTIFS(Tickets!G:G,A8,Tickets!I:I,"Open") -> 2 | D8: =COUNTIFS(Tickets!G:G,A8,Tickets!I:I,"In Progress") -> 1 | E8: =COUNTIFS(Tickets!G:G,A8,Tickets!I:I,"Resolved") -> 3 | F8: =COUNTIFS(Tickets!G:G,A8,Tickets!I:I,"Closed") -> 7 | G8: =COUNTIFS(Tickets!G:G,A8,Tickets!Q:Q,"Yes") -> 8 | H8: =IFERROR(AVERAGEIFS(Tickets!P:P,Tickets!G:G,A8,Tickets!P:P,"<>"),0) -> 44.515 | K8: P3 - Medium | L8: =COUNTIF(Tickets!F:F,K8) -> 30 | M8: =COUNTIFS(Tickets!F:F,K8,Tickets!Q:Q,"No") -> 14 | N8: =COUNTIFS(Tickets!F:F,K8,Tickets!Q:Q,"Yes") -> 16 | O8: =IFERROR(M8/MAX(L8,1),0) -> 0.46666667 | P8: =IFERROR(AVERAGEIFS(Tickets!O:O,Tickets!F:F,K8,Tickets!O:O,"<>"),0) -> 22.687 | Q8: =IFERROR(AVERAGEIFS(Tickets!P:P,Tickets!F:F,K8,Tickets!P:P,"<>"),0) -> 40.094615
A9: Access & Security | B9: =COUNTIF(Tickets!G:G,A9) -> 8 | C9: =COUNTIFS(Tickets!G:G,A9,Tickets!I:I,"Open") -> 0 | D9: =COUNTIFS(Tickets!G:G,A9,Tickets!I:I,"In Progress") -> 2 | E9: =COUNTIFS(Tickets!G:G,A9,Tickets!I:I,"Resolved") -> 4 | F9: =COUNTIFS(Tickets!G:G,A9,Tickets!I:I,"Closed") -> 2 | G9: =COUNTIFS(Tickets!G:G,A9,Tickets!Q:Q,"Yes") -> 3 | H9: =IFERROR(AVERAGEIFS(Tickets!P:P,Tickets!G:G,A9,Tickets!P:P,"<>"),0) -> 60.763333 | K9: P4 - Low | L9: =COUNTIF(Tickets!F:F,K9) -> 11 | M9: =COUNTIFS(Tickets!F:F,K9,Tickets!Q:Q,"No") -> 7 | N9: =COUNTIFS(Tickets!F:F,K9,Tickets!Q:Q,"Yes") -> 4 | O9: =IFERROR(M9/MAX(L9,1),0) -> 0.63636364 | P9: =IFERROR(AVERAGEIFS(Tickets!O:O,Tickets!F:F,K9,Tickets!O:O,"<>"),0) -> 64.277273 | Q9: =IFERROR(AVERAGEIFS(Tickets!P:P,Tickets!F:F,K9,Tickets!P:P,"<>"),0) -> 110.85
A10: Email & Communication | B10: =COUNTIF(Tickets!G:G,A10) -> 7 | C10: =COUNTIFS(Tickets!G:G,A10,Tickets!I:I,"Open") -> 0 | D10: =COUNTIFS(Tickets!G:G,A10,Tickets!I:I,"In Progress") -> 1 | E10: =COUNTIFS(Tickets!G:G,A10,Tickets!I:I,"Resolved") -> 3 | F10: =COUNTIFS(Tickets!G:G,A10,Tickets!I:I,"Closed") -> 2 | G10: =COUNTIFS(Tickets!G:G,A10,Tickets!Q:Q,"Yes") -> 4 | H10: =IFERROR(AVERAGEIFS(Tickets!P:P,Tickets!G:G,A10,Tickets!P:P,"<>"),0) -> 33.836
A11: Printer | B11: =COUNTIF(Tickets!G:G,A11) -> 7 | C11: =COUNTIFS(Tickets!G:G,A11,Tickets!I:I,"Open") -> 0 | D11: =COUNTIFS(Tickets!G:G,A11,Tickets!I:I,"In Progress") -> 3 | E11: =COUNTIFS(Tickets!G:G,A11,Tickets!I:I,"Resolved") -> 3 | F11: =COUNTIFS(Tickets!G:G,A11,Tickets!I:I,"Closed") -> 1 | G11: =COUNTIFS(Tickets!G:G,A11,Tickets!Q:Q,"Yes") -> 3 | H11: =IFERROR(AVERAGEIFS(Tickets!P:P,Tickets!G:G,A11,Tickets!P:P,"<>"),0) -> 41.995
A12: Mobile Device | B12: =COUNTIF(Tickets!G:G,A12) -> 4 | C12: =COUNTIFS(Tickets!G:G,A12,Tickets!I:I,"Open") -> 0 | D12: =COUNTIFS(Tickets!G:G,A12,Tickets!I:I,"In Progress") -> 1 | E12: =COUNTIFS(Tickets!G:G,A12,Tickets!I:I,"Resolved") -> 0 | F12: =COUNTIFS(Tickets!G:G,A12,Tickets!I:I,"Closed") -> 3 | G12: =COUNTIFS(Tickets!G:G,A12,Tickets!Q:Q,"Yes") -> 1 | H12: =IFERROR(AVERAGEIFS(Tickets!P:P,Tickets!G:G,A12,Tickets!P:P,"<>"),0) -> 57.933333
A13: Other | B13: =COUNTIF(Tickets!G:G,A13) -> 6 | C13: =COUNTIFS(Tickets!G:G,A13,Tickets!I:I,"Open") -> 1 | D13: =COUNTIFS(Tickets!G:G,A13,Tickets!I:I,"In Progress") -> 2 | E13: =COUNTIFS(Tickets!G:G,A13,Tickets!I:I,"Resolved") -> 2 | F13: =COUNTIFS(Tickets!G:G,A13,Tickets!I:I,"Closed") -> 0 | G13: =COUNTIFS(Tickets!G:G,A13,Tickets!Q:Q,"Yes") -> 4 | H13: =IFERROR(AVERAGEIFS(Tickets!P:P,Tickets!G:G,A13,Tickets!P:P,"<>"),0) -> 8.44
A17: 👨‍💻 Technician Performance | K17: 📈 Monthly Ticket Trend (Last 6 Months)
A18: Tech ID | B18: Name | C18: Assigned | D18: Open | E18: Resolved | F18: SLA Compliance | G18: Avg Res. (hrs) | H18: CSAT | K18: Month | L18: New Tickets | M18: Resolved | N18: Backlog | O18: SLA Breach
A19: T001 | B19: Ahmed Al-Rashid | C19: =COUNTIF(Tickets!J:J,A19) -> 11 | D19: =COUNTIFS(Tickets!J:J,A19,Tickets!I:I,"Open") -> 2 | E19: =COUNTIFS(Tickets!J:J,A19,Tickets!I:I,"Resolved")+COUNTIFS(Tickets!J:J,A19,Tickets!I:I,"Closed") -> 6 | F19: =IFERROR(COUNTIFS(Tickets!J:J,A19,Tickets!Q:Q,"No")/MAX(COUNTIF(Tickets!J:J,A19),1),0) -> 0.45454545 | G19: =IFERROR(AVERAGEIFS(Tickets!P:P,Tickets!J:J,A19,Tickets!P:P,"<>"),0) -> 50.3 | H19: =IFERROR(AVERAGEIFS(Tickets!S:S,Tickets!J:J,A19,Tickets!S:S,"<>"),0) -> 3.3333333 | K19: Oct-2024 | L19: 0 | M19: 0 | N19: 0 | O19: 0
A20: T002 | B20: Sara Mohammed | C20: =COUNTIF(Tickets!J:J,A20) -> 11 | D20: =COUNTIFS(Tickets!J:J,A20,Tickets!I:I,"Open") -> 1 | E20: =COUNTIFS(Tickets!J:J,A20,Tickets!I:I,"Resolved")+COUNTIFS(Tickets!J:J,A20,Tickets!I:I,"Closed") -> 5 | F20: =IFERROR(COUNTIFS(Tickets!J:J,A20,Tickets!Q:Q,"No")/MAX(COUNTIF(Tickets!J:J,A20),1),0) -> 0.63636364 | G20: =IFERROR(AVERAGEIFS(Tickets!P:P,Tickets!J:J,A20,Tickets!P:P,"<>"),0) -> 43.256 | H20: =IFERROR(AVERAGEIFS(Tickets!S:S,Tickets!J:J,A20,Tickets!S:S,"<>"),0) -> 4 | K20: Nov-2024 | L20: 0 | M20: 0 | N20: 0 | O20: 0
A21: T003 | B21: Khalid Hassan | C21: =COUNTIF(Tickets!J:J,A21) -> 13 | D21: =COUNTIFS(Tickets!J:J,A21,Tickets!I:I,"Open") -> 2 | E21: =COUNTIFS(Tickets!J:J,A21,Tickets!I:I,"Resolved")+COUNTIFS(Tickets!J:J,A21,Tickets!I:I,"Closed") -> 10 | F21: =IFERROR(COUNTIFS(Tickets!J:J,A21,Tickets!Q:Q,"No")/MAX(COUNTIF(Tickets!J:J,A21),1),0) -> 0.38461538 | G21: =IFERROR(AVERAGEIFS(Tickets!P:P,Tickets!J:J,A21,Tickets!P:P,"<>"),0) -> 50.578 | H21: =IFERROR(AVERAGEIFS(Tickets!S:S,Tickets!J:J,A21,Tickets!S:S,"<>"),0) -> 3.9 | K21: Dec-2024 | L21: 0 | M21: 0 | N21: 0 | O21: 0
A22: T004 | B22: Fatima Al-Ali | C22: =COUNTIF(Tickets!J:J,A22) -> 9 | D22: =COUNTIFS(Tickets!J:J,A22,Tickets!I:I,"Open") -> 1 | E22: =COUNTIFS(Tickets!J:J,A22,Tickets!I:I,"Resolved")+COUNTIFS(Tickets!J:J,A22,Tickets!I:I,"Closed") -> 5 | F22: =IFERROR(COUNTIFS(Tickets!J:J,A22,Tickets!Q:Q,"No")/MAX(COUNTIF(Tickets!J:J,A22),1),0) -> 0.33333333 | G22: =IFERROR(AVERAGEIFS(Tickets!P:P,Tickets!J:J,A22,Tickets!P:P,"<>"),0) -> 33.386 | H22: =IFERROR(AVERAGEIFS(Tickets!S:S,Tickets!J:J,A22,Tickets!S:S,"<>"),0) -> 3.8 | K22: Jan-2025 | L22: 0 | M22: 0 | N22: 0 | O22: 0
A23: T005 | B23: Omar Yusuf | C23: =COUNTIF(Tickets!J:J,A23) -> 16 | D23: =COUNTIFS(Tickets!J:J,A23,Tickets!I:I,"Open") -> 1 | E23: =COUNTIFS(Tickets!J:J,A23,Tickets!I:I,"Resolved")+COUNTIFS(Tickets!J:J,A23,Tickets!I:I,"Closed") -> 10 | F23: =IFERROR(COUNTIFS(Tickets!J:J,A23,Tickets!Q:Q,"No")/MAX(COUNTIF(Tickets!J:J,A23),1),0) -> 0.625 | G23: =IFERROR(AVERAGEIFS(Tickets!P:P,Tickets!J:J,A23,Tickets!P:P,"<>"),0) -> 40.143 | H23: =IFERROR(AVERAGEIFS(Tickets!S:S,Tickets!J:J,A23,Tickets!S:S,"<>"),0) -> 4 | K23: Feb-2025 | L23: 0 | M23: 0 | N23: 0 | O23: 0
K24: Mar-2025 | L24: 0 | M24: 0 | N24: 0 | O24: 0

Sheet Aging Report
A1: ⏰ AGING TICKET REPORT
A2: Tracks open/in-progress tickets by age | Review daily | Escalate tickets > 7 days
A3: Ticket ID | B3: Created Date | C3: Priority | D3: Category | E3: Status | F3: Technician | G3: Days Open | H3: Age Bucket | I3: SLA Breached | J3: Customer | K3: Escalation Flag | L3: Action Required
A4: TKT-0049 | B4: 45645 | C4: P2 - High | D4: Other | E4: Open | F4: Omar Yusuf | G4: 89 | H4: > 30 Days | I4: Yes | J4: Noura Hamdan | K4: 🔴 ESCALATE | L4: Immediate escalation to manager
A5: TKT-0009 | B5: 45647 | C5: P3 - Medium | D5: Hardware | E5: Open | F5: Sara Mohammed | G5: 87 | H5: > 30 Days | I5: No | J5: Yousef Al-Mansoori | K5: 🟠 REVIEW | L5: Immediate escalation to manager
A6: TKT-0018 | B6: 45650 | C6: P4 - Low | D6: Hardware | E6: Open | F6: Ahmed Al-Rashid | G6: 84 | H6: > 30 Days | I6: Yes | J6: Dana Al-Suwaidi | K6: 🟠 REVIEW | L6: Immediate escalation to manager
A7: TKT-0045 | B7: 45650 | C7: P3 - Medium | D7: Hardware | E7: In Progress | F7: Sara Mohammed | G7: 84 | H7: > 30 Days | I7: Yes | J7: Dana Al-Suwaidi | K7: 🟠 REVIEW | L7: Immediate escalation to manager
A8: TKT-0008 | B8: 45659 | C8: P3 - Medium | D8: Network | E8: In Progress | F8: Fatima Al-Ali | G8: 75 | H8: > 30 Days | I8: No | J8: Dana Al-Suwaidi | K8: 🟠 REVIEW | L8: Immediate escalation to manager
A9: TKT-0059 | B9: 45665 | C9: P3 - Medium | D9: Software | E9: In Progress | F9: Ahmed Al-Rashid | G9: 69 | H9: > 30 Days | I9: Yes | J9: Mona Salem | K9: 🟠 REVIEW | L9: Immediate escalation to manager
A10: TKT-0047 | B10: 45666 | C10: P3 - Medium | D10: Access & Security | E10: In Progress | F10: Omar Yusuf | G10: 68 | H10: > 30 Days | I10: Yes | J10: Noura Hamdan | K10: 🟠 REVIEW | L10: Immediate escalation to manager
A11: TKT-0013 | B11: 45668 | C11: P3 - Medium | D11: Printer | E11: In Progress | F11: Omar Yusuf | G11: 66 | H11: > 30 Days | I11: No | J11: Rashed Khalil | K11: 🟠 REVIEW | L11: Immediate escalation to manager
A12: TKT-0041 | B12: 45668 | C12: P4 - Low | D12: Network | E12: Open | F12: Khalid Hassan | G12: 66 | H12: > 30 Days | I12: Yes | J12: Tariq Nasser | K12: 🟠 REVIEW | L12: Immediate escalation to manager
A13: TKT-0014 | B13: 45670 | C13: P2 - High | D13: Other | E13: In Progress | F13: Fatima Al-Ali | G13: 64 | H13: > 30 Days | I13: Yes | J13: Rashed Khalil | K13: 🔴 ESCALATE | L13: Immediate escalation to manager
A14: TKT-0044 | B14: 45678 | C14: P3 - Medium | D14: Other | E14: In Progress | F14: Sara Mohammed | G14: 56 | H14: > 30 Days | I14: No | J14: Dana Al-Suwaidi | K14: 🟠 REVIEW | L14: Immediate escalation to manager
A15: TKT-0031 | B15: 45684 | C15: P3 - Medium | D15: Printer | E15: In Progress | F15: Sara Mohammed | G15: 50 | H15: > 30 Days | I15: Yes | J15: Rashed Khalil | K15: 🟠 REVIEW | L15: Immediate escalation to manager
... A23: TKT-0028 | B23: 45718 | C23: P3 - Medium | D23: Printer | E23: In Progress | F23: Fatima Al-Ali | G23: 16 | H23: 15-30 Days | I23: Yes | J23: Yousef Al-Mansoori | K23: 🟠 REVIEW | L23: Immediate escalation to manager
A24: TKT-0002 | B24: 45729 | C24: P3 - Medium | D24: Software | E24: Open | F24: Fatima Al-Ali | G24: 5 | H24: 4-7 Days | I24: No | J24: Noura Hamdan | L24: Normal processing
A25: TKT-0054 | B25: 45734 | C25: P1 - Critical | D25: Network | E25: Reopened | F25: Omar Yusuf | G25: 0 | H25: 0-1 Days | I25: No | J25: Noura Hamdan | L25: Normal processing

Sheet DAX & Power BI Guide
A1: ⚡ DAX MEASURES & POWER BI IMPLEMENTATION GUIDE
A2: Copy-paste ready DAX measures | Step-by-step Power BI setup | Data model relationships
A4: ▶ All DAX measures below should be created in Power BI Desktop under the 'Tickets' table unless noted otherwise. Use Home → New Measure.
A6: 1. Total Tickets
A7: Measure Name: | B7: [Total Tickets]
A8: Total Tickets =
A9: COUNTROWS(Tickets)
A10: 💡 Counts all rows in the Tickets table. Use as the base denominator for all % calculations.
A12: 2. Open Tickets
A13: Measure Name: | B13: [Open Tickets]
A14: Open Tickets =
A15: CALCULATE(
A16: COUNTROWS(Tickets),
A17: Tickets[Status] IN {"Open", "In Progress", "Reopened"}
A18: )
A19: 💡 Counts tickets that are not yet resolved. This is your daily backlog number.
A21: 3. Resolved Tickets
A22: Measure Name: | B22: [Resolved Tickets]
A23: Resolved Tickets =
A24: CALCULATE(
A25: COUNTROWS(Tickets),
A26: Tickets[Status] IN {"Resolved", "Closed"}
A27: )
A28: 💡 Counts all completed tickets. Use to track throughput and team productivity.
A30: 4. SLA Compliance %
A31: Measure Name: | B31: [SLA Compliance %]
A32: SLA Compliance % =
A33: DIVIDE(
A34: CALCULATE(COUNTROWS(Tickets), Tickets[SLA Breached] = "No"),
A35: [Total Tickets],
A36: 0
A37: )
A38: 💡 Key metric. >90% overall, >95% for P1/P2. Add to a KPI card with target line.
A40: 5. SLA Breaches
A41: Measure Name: | B41: [SLA Breach Count]
A42: SLA Breach Count =
A43: CALCULATE(
A44: COUNTROWS(Tickets),
A45: Tickets[SLA Breached] = "Yes"
A46: )
...

Sheet CF & Alerts Guide
A1: 🚦 CONDITIONAL FORMATTING & ALERT RULES
A2: Apply these rules in Excel and Power BI for automatic visual alerts
A4: Excel — Conditional Formatting Rules
A5: SLA Breach Column (Q) | B5: Formula: =Q4="Yes" | Format: Red fill (#FADBD8), Red bold text | Apply to: Q4:Q500
A6: Priority Column (F) — P1 | B6: Formula: =F4="P1 - Critical" | Format: Dark red fill, White bold text | Apply to: F4:F500
A7: Priority Column (F) — P2 | B7: Formula: =F4="P2 - High" | Format: Orange fill, White bold text | Apply to: F4:F500
A8: Aging Open Tickets | B8: Formula: =AND(I4="Open",B4<=TODAY()-7) | Format: Red fill entire row | Apply to: A4:T500
A9: Response Time > SLA | B9: Formula: =O4>N4 | Format: Orange fill | Apply to: O4:O500
A10: Low CSAT (≤2) | B10: Formula: =AND(S4<>"",S4<=2) | Format: Red background | Apply to: S4:S500
A11: High CSAT (=5) | B11: Formula: =S4=5 | Format: Green background | Apply to: S4:S500
A12: Reopened Tickets | B12: Formula: =I4="Reopened" | Format: Purple fill | Apply to: A4:T500
A14: Power BI — KPI Card Targets
A15: SLA Compliance % Card | B15: Value: [SLA Compliance %] | Target: 0.90 | Status: Bad if < 0.85, Warning if < 0.90, Good if >= 0.90
A16: CSAT Score Card | B16: Value: [CSAT Average] | Target: 4.0 | Status: Bad if < 3.5, Warning if < 4.0, Good if >= 4.0
A17: Open Tickets Card | B17: Value: [Open Tickets] | Target: 20 | Status: Bad if > 30, Warning if > 20, Good if <= 20
A18: P1 SLA Compliance Card | B18: Value: [P1 SLA Compliance %] | Target: 0.98 | Status: Bad if < 0.95, Good if >= 0.98
A19: Aging Tickets Card | B19: Value: [Aging Tickets 7d+] | Target: 0 | Status: Bad if > 5, Warning if > 0, Good if = 0
A21: Power BI — Table Conditional Formatting
A22: Resolution Time Column | B22: Background color: Red scale. Min = 0 (white), Max = SLA target * 2 (red). Highlights slow resolution.
A23: SLA Breached Column | B23: Rules: Yes = Red (#FADBD8), No = Green (#D5F5E3). Apply by field value.
A24: Priority Column | B24: Rules: P1=Dark Red, P2=Orange, P3=Gold, P4=Teal. Use 'Format by field value' with color table.
A25: Satisfaction Score | B25: Icon set: 5=Green circle, 4=Yellow circle, ≤3=Red circle. Use 'Icons' formatting option.
A26: Days Open (Aging Table) | B26: Data bars: min 0, max 30. Red gradient. Shows at a glance which tickets are oldest.
A28: Alert Automation Ideas
A29: Power Automate — P1 Alert | B29: Trigger: When ticket added with Priority=P1 → Send Teams message to IT Manager with ticket details immediately
A30: Power Automate — SLA Warning | B30: Trigger: Scheduled (every 30 min) → Query tickets approaching SLA → Post to Teams helpdesk channel
A31: Power Automate — Daily Digest | B31: Trigger: Weekday 8:00 AM → Get open tickets count → Email IT Manager with KPI summary
A32: Apps Script (Google) | B32: Trigger: onEdit → If status column changes to 'Open' → Send email to assigned technician automatically
A33: Power BI Alerts | B33: Pin KPI cards to dashboard → Set alert: Notify me if Open Tickets > 30 or SLA % drops below 85%
