Workbook

Sheet Dashboard
A1: 📊 IT ASSET MANAGEMENT DASHBOARD
A2: Live KPI Overview | As of: =TEXT(TODAY(),"DD-MMM-YYYY")
A4: Total Assets | E4: In Use | I4: Available | M4: Under Repair
A6: =COUNTA('Asset Register'!A4:A500)-COUNTBLANK('Asset Register'!A4:A500) -> -397 | E6: =COUNTIF('Asset Register'!Q4:Q500,"In Use") -> 43 | I6: =COUNTIF('Asset Register'!Q4:Q500,"Available") -> 3 | M6: =COUNTIF('Asset Register'!Q4:Q500,"Under Repair") -> 3
A8: assets | E8: assets | I8: assets | M8: assets
A10: Retired / Lost | E10: Open Maintenance | I10: Expiring Warranties (90d) | M10: Open Transactions
A12: =COUNTIF('Asset Register'!Q4:Q500,"Retired")+COUNTIF('Asset Register'!Q4:Q500,"Lost/Stolen") -> 0 | E12: =COUNTIF(Maintenance!Q4:Q500,"Open")+COUNTIF(Maintenance!Q4:Q500,"In Progress") -> 2 | I12: =COUNTIF('Warranty Alerts'!G5:G200,"🟠 Warning")+COUNTIF('Warranty Alerts'!G5:G200,"🔴 Critical") -> 4 | M12: =COUNTIF(Transactions!M4:M500,"Open") -> 25
A14: count | E14: count | I14: count | M14: count
A16: 📦 Assets by Category | I16: 🏢 Assets by Department
A17: Category | B17: Total | C17: In Use | D17: Available | E17: Under Repair | F17: Retired | G17: % In Use | I17: Department | J17: Total Assets | K17: In Use | L17: Available | M17: Maintenance Cost (QAR)
A18: Laptop | B18: =COUNTIF('Asset Register'!C:C,A18) -> 5 | C18: =COUNTIFS('Asset Register'!C:C,A18,'Asset Register'!Q:Q,"In Use") -> 4 | D18: =COUNTIFS('Asset Register'!C:C,A18,'Asset Register'!Q:Q,"Available") -> 1 | E18: =COUNTIFS('Asset Register'!C:C,A18,'Asset Register'!Q:Q,"Under Repair") -> 0 | F18: =COUNTIFS('Asset Register'!C:C,A18,'Asset Register'!Q:Q,"Retired") -> 0 | G18: =IFERROR(C18/B18,0) -> 0.8 | I18: IT | J18: =COUNTIF('Asset Register'!N:N,I18) -> 7 | K18: =COUNTIFS('Asset Register'!N:N,I18,'Asset Register'!Q:Q,"In Use") -> 7 | L18: =COUNTIFS('Asset Register'!N:N,I18,'Asset Register'!Q:Q,"Available") -> 0 | M18: =SUMIF(Maintenance!E:E,I18,Maintenance!N:N) -> 4741.32
A19: Desktop | B19: =COUNTIF('Asset Register'!C:C,A19) -> 5 | C19: =COUNTIFS('Asset Register'!C:C,A19,'Asset Register'!Q:Q,"In Use") -> 4 | D19: =COUNTIFS('Asset Register'!C:C,A19,'Asset Register'!Q:Q,"Available") -> 0 | E19: =COUNTIFS('Asset Register'!C:C,A19,'Asset Register'!Q:Q,"Under Repair") -> 1 | F19: =COUNTIFS('Asset Register'!C:C,A19,'Asset Register'!Q:Q,"Retired") -> 0 | G19: =IFERROR(C19/B19,0) -> 0.8 | I19: Finance | J19: =COUNTIF('Asset Register'!N:N,I19) -> 7 | K19: =COUNTIFS('Asset Register'!N:N,I19,'Asset Register'!Q:Q,"In Use") -> 5 | L19: =COUNTIFS('Asset Register'!N:N,I19,'Asset Register'!Q:Q,"Available") -> 2 | M19: =SUMIF(Maintenance!E:E,I19,Maintenance!N:N) -> 0
A20: Monitor | B20: =COUNTIF('Asset Register'!C:C,A20) -> 5 | C20: =COUNTIFS('Asset Register'!C:C,A20,'Asset Register'!Q:Q,"In Use") -> 5 | D20: =COUNTIFS('Asset Register'!C:C,A20,'Asset Register'!Q:Q,"Available") -> 0 | E20: =COUNTIFS('Asset Register'!C:C,A20,'Asset Register'!Q:Q,"Under Repair") -> 0 | F20: =COUNTIFS('Asset Register'!C:C,A20,'Asset Register'!Q:Q,"Retired") -> 0 | G20: =IFERROR(C20/B20,0) -> 1 | I20: HR | J20: =COUNTIF('Asset Register'!N:N,I20) -> 6 | K20: =COUNTIFS('Asset Register'!N:N,I20,'Asset Register'!Q:Q,"In Use") -> 3 | L20: =COUNTIFS('Asset Register'!N:N,I20,'Asset Register'!Q:Q,"Available") -> 1 | M20: =SUMIF(Maintenance!E:E,I20,Maintenance!N:N) -> 4516.91
A21: Printer | B21: =COUNTIF('Asset Register'!C:C,A21) -> 5 | C21: =COUNTIFS('Asset Register'!C:C,A21,'Asset Register'!Q:Q,"In Use") -> 4 | D21: =COUNTIFS('Asset Register'!C:C,A21,'Asset Register'!Q:Q,"Available") -> 1 | E21: =COUNTIFS('Asset Register'!C:C,A21,'Asset Register'!Q:Q,"Under Repair") -> 0 | F21: =COUNTIFS('Asset Register'!C:C,A21,'Asset Register'!Q:Q,"Retired") -> 0 | G21: =IFERROR(C21/B21,0) -> 0.8 | I21: Operations | J21: =COUNTIF('Asset Register'!N:N,I21) -> 6 | K21: =COUNTIFS('Asset Register'!N:N,I21,'Asset Register'!Q:Q,"In Use") -> 6 | L21: =COUNTIFS('Asset Register'!N:N,I21,'Asset Register'!Q:Q,"Available") -> 0 | M21: =SUMIF(Maintenance!E:E,I21,Maintenance!N:N) -> 0
A22: Server | B22: =COUNTIF('Asset Register'!C:C,A22) -> 5 | C22: =COUNTIFS('Asset Register'!C:C,A22,'Asset Register'!Q:Q,"In Use") -> 4 | D22: =COUNTIFS('Asset Register'!C:C,A22,'Asset Register'!Q:Q,"Available") -> 0 | E22: =COUNTIFS('Asset Register'!C:C,A22,'Asset Register'!Q:Q,"Under Repair") -> 1 | F22: =COUNTIFS('Asset Register'!C:C,A22,'Asset Register'!Q:Q,"Retired") -> 0 | G22: =IFERROR(C22/B22,0) -> 0.8 | I22: Marketing | J22: =COUNTIF('Asset Register'!N:N,I22) -> 6 | K22: =COUNTIFS('Asset Register'!N:N,I22,'Asset Register'!Q:Q,"In Use") -> 6 | L22: =COUNTIFS('Asset Register'!N:N,I22,'Asset Register'!Q:Q,"Available") -> 0 | M22: =SUMIF(Maintenance!E:E,I22,Maintenance!N:N) -> 3819.43
A23: Network | B23: =COUNTIF('Asset Register'!C:C,A23) -> 5 | C23: =COUNTIFS('Asset Register'!C:C,A23,'Asset Register'!Q:Q,"In Use") -> 4 | D23: =COUNTIFS('Asset Register'!C:C,A23,'Asset Register'!Q:Q,"Available") -> 0 | E23: =COUNTIFS('Asset Register'!C:C,A23,'Asset Register'!Q:Q,"Under Repair") -> 0 | F23: =COUNTIFS('Asset Register'!C:C,A23,'Asset Register'!Q:Q,"Retired") -> 0 | G23: =IFERROR(C23/B23,0) -> 0.8 | I23: Sales | J23: =COUNTIF('Asset Register'!N:N,I23) -> 6 | K23: =COUNTIFS('Asset Register'!N:N,I23,'Asset Register'!Q:Q,"In Use") -> 4 | L23: =COUNTIFS('Asset Register'!N:N,I23,'Asset Register'!Q:Q,"Available") -> 0 | M23: =SUMIF(Maintenance!E:E,I23,Maintenance!N:N) -> 0
A24: Phone | B24: =COUNTIF('Asset Register'!C:C,A24) -> 5 | C24: =COUNTIFS('Asset Register'!C:C,A24,'Asset Register'!Q:Q,"In Use") -> 4 | D24: =COUNTIFS('Asset Register'!C:C,A24,'Asset Register'!Q:Q,"Available") -> 0 | E24: =COUNTIFS('Asset Register'!C:C,A24,'Asset Register'!Q:Q,"Under Repair") -> 1 | F24: =COUNTIFS('Asset Register'!C:C,A24,'Asset Register'!Q:Q,"Retired") -> 0 | G24: =IFERROR(C24/B24,0) -> 0.8 | I24: Legal | J24: =COUNTIF('Asset Register'!N:N,I24) -> 6 | K24: =COUNTIFS('Asset Register'!N:N,I24,'Asset Register'!Q:Q,"In Use") -> 6 | L24: =COUNTIFS('Asset Register'!N:N,I24,'Asset Register'!Q:Q,"Available") -> 0 | M24: =SUMIF(Maintenance!E:E,I24,Maintenance!N:N) -> 2979.11
A25: Tablet | B25: =COUNTIF('Asset Register'!C:C,A25) -> 5 | C25: =COUNTIFS('Asset Register'!C:C,A25,'Asset Register'!Q:Q,"In Use") -> 5 | D25: =COUNTIFS('Asset Register'!C:C,A25,'Asset Register'!Q:Q,"Available") -> 0 | E25: =COUNTIFS('Asset Register'!C:C,A25,'Asset Register'!Q:Q,"Under Repair") -> 0 | F25: =COUNTIFS('Asset Register'!C:C,A25,'Asset Register'!Q:Q,"Retired") -> 0 | G25: =IFERROR(C25/B25,0) -> 1 | I25: Executive | J25: =COUNTIF('Asset Register'!N:N,I25) -> 6 | K25: =COUNTIFS('Asset Register'!N:N,I25,'Asset Register'!Q:Q,"In Use") -> 6 | L25: =COUNTIFS('Asset Register'!N:N,I25,'Asset Register'!Q:Q,"Available") -> 0 | M25: =SUMIF(Maintenance!E:E,I25,Maintenance!N:N) -> 0
A26: Projector | B26: =COUNTIF('Asset Register'!C:C,A26) -> 5 | C26: =COUNTIFS('Asset Register'!C:C,A26,'Asset Register'!Q:Q,"In Use") -> 5 | D26: =COUNTIFS('Asset Register'!C:C,A26,'Asset Register'!Q:Q,"Available") -> 0 | E26: =COUNTIFS('Asset Register'!C:C,A26,'Asset Register'!Q:Q,"Under Repair") -> 0 | F26: =COUNTIFS('Asset Register'!C:C,A26,'Asset Register'!Q:Q,"Retired") -> 0 | G26: =IFERROR(C26/B26,0) -> 1
A27: UPS | B27: =COUNTIF('Asset Register'!C:C,A27) -> 5 | C27: =COUNTIFS('Asset Register'!C:C,A27,'Asset Register'!Q:Q,"In Use") -> 4 | D27: =COUNTIFS('Asset Register'!C:C,A27,'Asset Register'!Q:Q,"Available") -> 1 | E27: =COUNTIFS('Asset Register'!C:C,A27,'Asset Register'!Q:Q,"Under Repair") -> 0 | F27: =COUNTIFS('Asset Register'!C:C,A27,'Asset Register'!Q:Q,"Retired") -> 0 | G27: =IFERROR(C27/B27,0) -> 0.8
A28: TOTAL | B28: =SUM(B18:B27) -> 50 | C28: =SUM(C18:C27) -> 43 | D28: =SUM(D18:D27) -> 3 | E28: =SUM(E18:E27) -> 3 | F28: =SUM(F18:F27) -> 0 | G28: =IFERROR(C28/B28,0) -> 0.86
I32: Status Distribution
I33: In Use | J33: =COUNTIF('Asset Register'!Q:Q,I33) -> 43
I34: Available | J34: =COUNTIF('Asset Register'!Q:Q,I34) -> 3
I35: Under Repair | J35: =COUNTIF('Asset Register'!Q:Q,I35) -> 3
I36: Retired | J36: =COUNTIF('Asset Register'!Q:Q,I36) -> 0
I37: Lost/Stolen | J37: =COUNTIF('Asset Register'!Q:Q,I37) -> 0
I38: In Storage | J38: =COUNTIF('Asset Register'!Q:Q,I38) -> 1

Sheet Asset Register
A1: 🖥️ IT ASSET REGISTER
A2: Central repository of all IT assets | Last Updated: =TODAY()
A3: Asset ID | B3: Asset Name | C3: Category | D3: Sub-Category | E3: Brand | F3: Model | G3: Serial Number | H3: Purchase Date | I3: Purchase Price | J3: Vendor | K3: Warranty Start | L3: Warranty End | M3: Warranty Status | N3: Department | O3: Location | P3: Assigned To | Q3: Status | R3: Condition | S3: OS / Version | T3: Notes
A4: LAP-001 | B4: Samsung Laptop | C4: Laptop | E4: Samsung | F4: Samsung Pro X1 | G4: SN13356886 | H4: 45506 | I4: 2336.69 | J4: HP Enterprise | K4: 45506 | L4: 46601 | M4: =IF(L4="","N/A",IF(L4<TODAY(),"Expired",IF(L4<TODAY()+90,"Expiring Soon","Active"))) -> Active | N4: IT | O4: HQ - Floor 1 | P4: Yousef Al-Mansoori | Q4: In Use | R4: Excellent | S4: iOS 17
A5: DES-001 | B5: Lenovo Desktop | C5: Desktop | E5: Lenovo | F5: Lenovo Plus X1 | G5: SN13999315 | H5: 45878 | I5: 2139.78 | J5: Cisco | K5: 45878 | L5: 46973 | M5: =IF(L5="","N/A",IF(L5<TODAY(),"Expired",IF(L5<TODAY()+90,"Expiring Soon","Active"))) -> Active | N5: Finance | O5: HQ - Floor 1 | P5: Noura Hamdan | Q5: In Use | R5: Poor | S5: macOS Sonoma
A6: MON-001 | B6: Lenovo Monitor | C6: Monitor | E6: Lenovo | F6: Lenovo Pro 14 | G6: SN47338124 | H6: 46056 | I6: 6191.06 | J6: HP Enterprise | K6: 46056 | L6: 47151 | M6: =IF(L6="","N/A",IF(L6<TODAY(),"Expired",IF(L6<TODAY()+90,"Expiring Soon","Active"))) -> Active | N6: HR | O6: Branch - Dubai | P6: Khalid Hassan | Q6: In Use | R6: Good
A7: PRN-001 | B7: Apple Printer | C7: Printer | E7: Apple | F7: Apple Plus X1 | G7: SN22448136 | H7: 45291 | I7: 1225.37 | J7: Epson | K7: 45291 | L7: 46021 | M7: =IF(L7="","N/A",IF(L7<TODAY(),"Expired",IF(L7<TODAY()+90,"Expiring Soon","Active"))) -> Expired | N7: Operations | O7: Branch - Abu Dhabi | P7: Ahmed Al-Rashid | Q7: In Use | R7: Poor
A8: SRV-001 | B8: Cisco Server | C8: Server | E8: Cisco | F8: Cisco Pro X1 | G8: SN60806024 | H8: 45908 | I8: 4640.3 | J8: Epson | K8: 45908 | L8: 47003 | M8: =IF(L8="","N/A",IF(L8<TODAY(),"Expired",IF(L8<TODAY()+90,"Expiring Soon","Active"))) -> Active | N8: Marketing | O8: Branch - Abu Dhabi | P8: Layla Ibrahim | Q8: In Use | R8: Good
A9: NET-001 | B9: Dell Network | C9: Network | E9: Dell | F9: Dell Plus X1 | G9: SN98753260 | H9: 45603 | I9: 6298.01 | J9: Dell Technologies | K9: 45603 | L9: 45968 | M9: =IF(L9="","N/A",IF(L9<TODAY(),"Expired",IF(L9<TODAY()+90,"Expiring Soon","Active"))) -> Expired | N9: Sales | O9: Warehouse | Q9: In Storage | R9: Poor
A10: PHN-001 | B10: Apple Phone | C10: Phone | E10: Apple | F10: Apple Pro X5 | G10: SN59684848 | H10: 45342 | I10: 2071.3 | J10: Apple | K10: 45342 | L10: 46437 | M10: =IF(L10="","N/A",IF(L10<TODAY(),"Expired",IF(L10<TODAY()+90,"Expiring Soon","Active"))) -> Active | N10: Legal | O10: Data Center | P10: Hessa Al-Zaabi | Q10: In Use | R10: Good | S10: iOS 17
A11: TAB-001 | B11: Samsung Tablet | C11: Tablet | E11: Samsung | F11: Samsung Plus X5 | G11: SN31931511 | H11: 45123 | I11: 3345.92 | J11: Samsung | K11: 45123 | L11: 46218 | M11: =IF(L11="","N/A",IF(L11<TODAY(),"Expired",IF(L11<TODAY()+90,"Expiring Soon","Active"))) -> Active | N11: Executive | O11: Branch - Abu Dhabi | P11: Layla Ibrahim | Q11: In Use | R11: Excellent | S11: macOS Sonoma
A12: PRJ-001 | B12: Dell Projector | C12: Projector | E12: Dell | F12: Dell Pro G3 | G12: SN63843426 | H12: 45521 | I12: 996.41 | J12: Cisco | K12: 45521 | L12: 46616 | M12: =IF(L12="","N/A",IF(L12<TODAY(),"Expired",IF(L12<TODAY()+90,"Expiring Soon","Active"))) -> Active | N12: IT | O12: HQ - Floor 3 | P12: Mona Salem | Q12: In Use | R12: Poor
A13: UPS-001 | B13: Samsung UPS | C13: UPS | E13: Samsung | F13: Samsung Plus G5 | G13: SN29175900 | H13: 45527 | I13: 1547.23 | J13: Samsung | K13: 45527 | L13: 46622 | M13: =IF(L13="","N/A",IF(L13<TODAY(),"Expired",IF(L13<TODAY()+90,"Expiring Soon","Active"))) -> Active | N13: Finance | O13: Branch - Abu Dhabi | P13: Hessa Al-Zaabi | Q13: In Use | R13: Poor
A14: LAP-002 | B14: Cisco Laptop | C14: Laptop | E14: Cisco | F14: Cisco Pro G5 | G14: SN58586340 | H14: 45620 | I14: 7979.94 | J14: HP Enterprise | K14: 45620 | L14: 46715 | M14: =IF(L14="","N/A",IF(L14<TODAY(),"Expired",IF(L14<TODAY()+90,"Expiring Soon","Active"))) -> Active | N14: HR | O14: Branch - Dubai | Q14: Available | R14: Excellent | S14: macOS Sonoma
A15: DES-002 | B15: Samsung Desktop | C15: Desktop | E15: Samsung | F15: Samsung Plus X5 | G15: SN66661351 | H15: 45939 | I15: 3385.75 | J15: Cisco | K15: 45939 | L15: 46669 | M15: =IF(L15="","N/A",IF(L15<TODAY(),"Expired",IF(L15<TODAY()+90,"Expiring Soon","Active"))) -> Active | N15: Operations | O15: Branch - Abu Dhabi | P15: Yousef Al-Mansoori | Q15: In Use | R15: Excellent
A16: MON-002 | B16: Samsung Monitor | C16: Monitor | E16: Samsung | F16: Samsung Pro X1 | G16: SN82070937 | H16: 45523 | I16: 6264.49 | J16: Apple | K16: 45523 | L16: 45888 | M16: =IF(L16="","N/A",IF(L16<TODAY(),"Expired",IF(L16<TODAY()+90,"Expiring Soon","Active"))) -> Expired | N16: Marketing | O16: HQ - Floor 3 | P16: Mona Salem | Q16: In Use | R16: Excellent
A17: PRN-002 | B17: Samsung Printer | C17: Printer | E17: Samsung | F17: Samsung Plus 15 | G17: SN45351479 | H17: 45044 | I17: 6214.72 | J17: Cisco | K17: 45044 | L17: 45409 | M17: =IF(L17="","N/A",IF(L17<TODAY(),"Expired",IF(L17<TODAY()+90,"Expiring Soon","Active"))) -> Expired | N17: Sales | O17: Warehouse | P17: Rashed Khalil | Q17: In Use | R17: Good
A18: SRV-002 | B18: HP Server | C18: Server | E18: HP | F18: HP Pro G3 | G18: SN31682744 | H18: 44965 | I18: 7651.25 | J18: Cisco | K18: 44965 | L18: 45330 | M18: =IF(L18="","N/A",IF(L18<TODAY(),"Expired",IF(L18<TODAY()+90,"Expiring Soon","Active"))) -> Expired | N18: Legal | O18: Branch - Abu Dhabi | P18: Ahmed Al-Rashid | Q18: In Use | R18: Excellent | S18: Ubuntu 22.04
A19: NET-002 | B19: Apple Network | C19: Network | E19: Apple | F19: Apple Plus X5 | G19: SN17774584 | H19: 45576 | I19: 7085.07 | J19: Dell Technologies | K19: 45576 | L19: 45941 | M19: =IF(L19="","N/A",IF(L19<TODAY(),"Expired",IF(L19<TODAY()+90,"Expiring Soon","Active"))) -> Expired | N19: Executive | O19: Data Center | P19: Sara Mohammed | Q19: In Use | R19: Good | S19: macOS Sonoma
A20: PHN-002 | B20: Samsung Phone | C20: Phone | E20: Samsung | F20: Samsung Pro G5 | G20: SN83793389 | H20: 45731 | I20: 2487.92 | J20: Epson | K20: 45731 | L20: 46826 | M20: =IF(L20="","N/A",IF(L20<TODAY(),"Expired",IF(L20<TODAY()+90,"Expiring Soon","Active"))) -> Active | N20: IT | O20: Branch - Dubai | P20: Yousef Al-Mansoori | Q20: In Use | R20: Good
A21: TAB-002 | B21: Apple Tablet | C21: Tablet | E21: Apple | F21: Apple Plus G5 | G21: SN97225156 | H21: 45305 | I21: 3785.75 | J21: Cisco | K21: 45305 | L21: 46035 | M21: =IF(L21="","N/A",IF(L21<TODAY(),"Expired",IF(L21<TODAY()+90,"Expiring Soon","Active"))) -> Expired | N21: Finance | O21: HQ - Floor 1 | P21: Sara Mohammed | Q21: In Use | R21: Fair | S21: Windows 11 Pro
A22: PRJ-002 | B22: Cisco Projector | C22: Projector | E22: Cisco | F22: Cisco Pro 14 | G22: SN40885476 | H22: 45618 | I22: 553.93 | J22: Samsung | K22: 45618 | L22: 46713 | M22: =IF(L22="","N/A",IF(L22<TODAY(),"Expired",IF(L22<TODAY()+90,"Expiring Soon","Active"))) -> Active | N22: HR | O22: HQ - Floor 1 | P22: Ahmed Al-Rashid | Q22: In Use | R22: Fair
A23: UPS-002 | B23: Dell UPS | C23: UPS | E23: Dell | F23: Dell Plus 14 | G23: SN41944441 | H23: 45499 | I23: 5517.33 | J23: HP Enterprise | K23: 45499 | L23: 46594 | M23: =IF(L23="","N/A",IF(L23<TODAY(),"Expired",IF(L23<TODAY()+90,"Expiring Soon","Active"))) -> Active | N23: Operations | O23: HQ - Floor 2 | P23: Hessa Al-Zaabi | Q23: In Use | R23: Poor
A24: LAP-003 | B24: HP Laptop | C24: Laptop | E24: HP | F24: HP Pro G5 | G24: SN64634663 | H24: 45680 | I24: 1207.44 | J24: Samsung | K24: 45680 | L24: 46410 | M24: =IF(L24="","N/A",IF(L24<TODAY(),"Expired",IF(L24<TODAY()+90,"Expiring Soon","Active"))) -> Active | N24: Marketing | O24: HQ - Floor 3 | P24: Mona Salem | Q24: In Use | R24: Excellent
A25: DES-003 | B25: Samsung Desktop | C25: Desktop | E25: Samsung | F25: Samsung Plus 15 | G25: SN23209423 | H25: 45945 | I25: 3519.66 | J25: Apple | K25: 45945 | L25: 46310 | M25: =IF(L25="","N/A",IF(L25<TODAY(),"Expired",IF(L25<TODAY()+90,"Expiring Soon","Active"))) -> Active | N25: Sales | O25: HQ - Floor 2 | Q25: Under Repair | R25: Poor | S25: macOS Sonoma
A26: MON-003 | B26: Lenovo Monitor | C26: Monitor | E26: Lenovo | F26: Lenovo Pro X5 | G26: SN47385696 | H26: 45122 | I26: 2373.55 | J26: Dell Technologies | K26: 45122 | L26: 45852 | M26: =IF(L26="","N/A",IF(L26<TODAY(),"Expired",IF(L26<TODAY()+90,"Expiring Soon","Active"))) -> Expired | N26: Legal | O26: Warehouse | P26: Yousef Al-Mansoori | Q26: In Use | R26: Excellent
A27: PRN-003 | B27: Dell Printer | C27: Printer | E27: Dell | F27: Dell Plus 15 | G27: SN82556484 | H27: 46039 | I27: 7767.47 | J27: Epson | K27: 46039 | L27: 46404 | M27: =IF(L27="","N/A",IF(L27<TODAY(),"Expired",IF(L27<TODAY()+90,"Expiring Soon","Active"))) -> Active | N27: Executive | O27: HQ - Floor 2 | P27: Mona Salem | Q27: In Use | R27: Good
A28: SRV-003 | B28: Lenovo Server | C28: Server | E28: Lenovo | F28: Lenovo Pro X1 | G28: SN32097220 | H28: 45293 | I28: 516.17 | J28: Lenovo | K28: 45293 | L28: 46023 | M28: =IF(L28="","N/A",IF(L28<TODAY(),"Expired",IF(L28<TODAY()+90,"Expiring Soon","Active"))) -> Expired | N28: IT | O28: Warehouse | P28: Omar Yusuf | Q28: In Use | R28: Poor
A29: NET-003 | B29: Samsung Network | C29: Network | E29: Samsung | F29: Samsung Plus 14 | G29: SN98834863 | H29: 45073 | I29: 1660.98 | J29: Apple | K29: 45073 | L29: 45438 | M29: =IF(L29="","N/A",IF(L29<TODAY(),"Expired",IF(L29<TODAY()+90,"Expiring Soon","Active"))) -> Expired | N29: Finance | O29: HQ - Floor 1 | P29: Yousef Al-Mansoori | Q29: In Use | R29: Excellent
A30: PHN-003 | B30: Apple Phone | C30: Phone | E30: Apple | F30: Apple Pro X1 | G30: SN16729990 | H30: 45093 | I30: 4271.38 | J30: Epson | K30: 45093 | L30: 46188 | M30: =IF(L30="","N/A",IF(L30<TODAY(),"Expired",IF(L30<TODAY()+90,"Expiring Soon","Active"))) -> Expiring Soon | N30: HR | O30: HQ - Floor 2 | Q30: Under Repair | R30: Excellent | S30: macOS Sonoma
A31: TAB-003 | B31: Dell Tablet | C31: Tablet | E31: Dell | F31: Dell Plus 14 | G31: SN19121552 | H31: 45588 | I31: 3528.32 | J31: Cisco | K31: 45588 | L31: 45953 | M31: =IF(L31="","N/A",IF(L31<TODAY(),"Expired",IF(L31<TODAY()+90,"Expiring Soon","Active"))) -> Expired | N31: Operations | O31: Branch - Abu Dhabi | P31: Hessa Al-Zaabi | Q31: In Use | R31: Excellent | S31: Windows 10
A32: PRJ-003 | B32: Samsung Projector | C32: Projector | E32: Samsung | F32: Samsung Pro 14 | G32: SN85863473 | H32: 44999 | I32: 2872.77 | J32: Apple | K32: 44999 | L32: 45364 | M32: =IF(L32="","N/A",IF(L32<TODAY(),"Expired",IF(L32<TODAY()+90,"Expiring Soon","Active"))) -> Expired | N32: Marketing | O32: Data Center | P32: Fatima Al-Ali | Q32: In Use | R32: Fair
A33: UPS-003 | B33: Lenovo UPS | C33: UPS | E33: Lenovo | F33: Lenovo Plus X5 | G33: SN96637649 | H33: 45455 | I33: 3929.18 | J33: Epson | K33: 45455 | L33: 45820 | M33: =IF(L33="","N/A",IF(L33<TODAY(),"Expired",IF(L33<TODAY()+90,"Expiring Soon","Active"))) -> Expired | N33: Sales | O33: HQ - Floor 1 | P33: Hessa Al-Zaabi | Q33: In Use | R33: Excellent
A34: LAP-004 | B34: Dell Laptop | C34: Laptop | E34: Dell | F34: Dell Pro 14 | G34: SN38609087 | H34: 45033 | I34: 2489 | J34: Apple | K34: 45033 | L34: 45398 | M34: =IF(L34="","N/A",IF(L34<TODAY(),"Expired",IF(L34<TODAY()+90,"Expiring Soon","Active"))) -> Expired | N34: Legal | O34: HQ - Floor 2 | P34: Khalid Hassan | Q34: In Use | R34: Poor | S34: iOS 17
A35: DES-004 | B35: Samsung Desktop | C35: Desktop | E35: Samsung | F35: Samsung Plus G3 | G35: SN92097999 | H35: 44986 | I35: 558.67 | J35: Epson | K35: 44986 | L35: 46081 | M35: =IF(L35="","N/A",IF(L35<TODAY(),"Expired",IF(L35<TODAY()+90,"Expiring Soon","Active"))) -> Expired | N35: Executive | O35: HQ - Floor 3 | P35: Sara Mohammed | Q35: In Use | R35: Good | S35: Ubuntu 22.04
A36: MON-004 | B36: Dell Monitor | C36: Monitor | E36: Dell | F36: Dell Pro X1 | G36: SN84252420 | H36: 45751 | I36: 2542.61 | J36: Cisco | K36: 45751 | L36: 46116 | M36: =IF(L36="","N/A",IF(L36<TODAY(),"Expired",IF(L36<TODAY()+90,"Expiring Soon","Active"))) -> Expiring Soon | N36: IT | O36: Data Center | P36: Rashed Khalil | Q36: In Use | R36: Fair
A37: PRN-004 | B37: Cisco Printer | C37: Printer | E37: Cisco | F37: Cisco Plus G5 | G37: SN43704923 | H37: 45965 | I37: 1192.24 | J37: Lenovo | K37: 45965 | L37: 46695 | M37: =IF(L37="","N/A",IF(L37<TODAY(),"Expired",IF(L37<TODAY()+90,"Expiring Soon","Active"))) -> Active | N37: Finance | O37: HQ - Floor 1 | Q37: Available | R37: Fair
A38: SRV-004 | B38: HP Server | C38: Server | E38: HP | F38: HP Pro 15 | G38: SN69302158 | H38: 44940 | I38: 5792.51 | J38: Cisco | K38: 44940 | L38: 45305 | M38: =IF(L38="","N/A",IF(L38<TODAY(),"Expired",IF(L38<TODAY()+90,"Expiring Soon","Active"))) -> Expired | N38: HR | O38: HQ - Floor 1 | Q38: Under Repair | R38: Good | S38: iOS 17
A39: NET-004 | B39: Dell Network | C39: Network | E39: Dell | F39: Dell Plus G3 | G39: SN88183110 | H39: 44938 | I39: 1610.7 | J39: HP Enterprise | K39: 44938 | L39: 45303 | M39: =IF(L39="","N/A",IF(L39<TODAY(),"Expired",IF(L39<TODAY()+90,"Expiring Soon","Active"))) -> Expired | N39: Operations | O39: HQ - Floor 3 | P39: Ahmed Al-Rashid | Q39: In Use | R39: Fair | S39: macOS Sonoma
A40: PHN-004 | B40: Samsung Phone | C40: Phone | E40: Samsung | F40: Samsung Pro X5 | G40: SN99514287 | H40: 45859 | I40: 3152.59 | J40: Cisco | K40: 45859 | L40: 46589 | M40: =IF(L40="","N/A",IF(L40<TODAY(),"Expired",IF(L40<TODAY()+90,"Expiring Soon","Active"))) -> Active | N40: Marketing | O40: Branch - Abu Dhabi | P40: Fatima Al-Ali | Q40: In Use | R40: Good | S40: macOS Sonoma
...

Sheet Users
A1: 👥 USERS & EMPLOYEES
A2: Directory of all staff eligible to hold IT assets
A3: Employee ID | B3: Full Name | C3: Email | D3: Department | E3: Job Title | F3: Location | G3: Phone | H3: Manager | I3: Status | J3: Asset Count | K3: Notes
A4: EMP-001 | B4: Ahmed Al-Rashid | C4: ahmed.al-rashid@company.qa | D4: Finance | E4: Coordinator | F4: HQ - Floor 1 | G4: +974 6806 9702 | H4: Omar Yusuf | I4: Active | J4: =COUNTIF('Asset Register'!P:P,B4) -> 4
A5: EMP-002 | B5: Sara Mohammed | C5: sara.mohammed@company.qa | D5: HR | E5: Specialist | F5: HQ - Floor 3 | G5: +974 5599 8251 | H5: Layla Ibrahim | I5: Active | J5: =COUNTIF('Asset Register'!P:P,B5) -> 3
A6: EMP-003 | B6: Khalid Hassan | C6: khalid.hassan@company.qa | D6: Operations | E6: Specialist | F6: HQ - Floor 3 | G6: +974 7135 7991 | H6: Tariq Nasser | I6: Active | J6: =COUNTIF('Asset Register'!P:P,B6) -> 2
A7: EMP-004 | B7: Fatima Al-Ali | C7: fatima.al-ali@company.qa | D7: Marketing | E7: Specialist | F7: HQ - Floor 2 | G7: +974 4303 8777 | H7: Mona Salem | I7: Active | J7: =COUNTIF('Asset Register'!P:P,B7) -> 4
A8: EMP-005 | B8: Omar Yusuf | C8: omar.yusuf@company.qa | D8: Sales | E8: Coordinator | F8: HQ - Floor 2 | G8: +974 5025 5543 | H8: Yousef Al-Mansoori | I8: Active | J8: =COUNTIF('Asset Register'!P:P,B8) -> 3
A9: EMP-006 | B9: Layla Ibrahim | C9: layla.ibrahim@company.qa | D9: Legal | E9: Specialist | F9: HQ - Floor 2 | G9: +974 4959 5499 | H9: Hessa Al-Zaabi | I9: Active | J9: =COUNTIF('Asset Register'!P:P,B9) -> 3
A10: EMP-007 | B10: Tariq Nasser | C10: tariq.nasser@company.qa | D10: Executive | E10: Coordinator | F10: HQ - Floor 1 | G10: +974 5340 4841 | H10: Rashed Khalil | I10: Active | J10: =COUNTIF('Asset Register'!P:P,B10) -> 1
A11: EMP-008 | B11: Mona Salem | C11: mona.salem@company.qa | D11: IT | E11: Engineer | F11: HQ - Floor 2 | G11: +974 5619 9849 | H11: Noura Hamdan | I11: Active | J11: =COUNTIF('Asset Register'!P:P,B11) -> 5
A12: EMP-009 | B12: Yousef Al-Mansoori | C12: yousef.al-mansoori@company.qa | D12: Finance | E12: Manager | F12: HQ - Floor 1 | G12: +974 4235 4788 | H12: Ahmed Al-Rashid | I12: Active | J12: =COUNTIF('Asset Register'!P:P,B12) -> 6
A13: EMP-010 | B13: Hessa Al-Zaabi | C13: hessa.al-zaabi@company.qa | D13: HR | E13: Coordinator | F13: HQ - Floor 3 | G13: +974 4251 4505 | H13: Sara Mohammed | I13: Active | J13: =COUNTIF('Asset Register'!P:P,B13) -> 6
A14: EMP-011 | B14: Rashed Khalil | C14: rashed.khalil@company.qa | D14: Operations | E14: Manager | F14: HQ - Floor 2 | G14: +974 6339 6421 | H14: Khalid Hassan | I14: Active | J14: =COUNTIF('Asset Register'!P:P,B14) -> 4
A15: EMP-012 | B15: Noura Hamdan | C15: noura.hamdan@company.qa | D15: Marketing | E15: Specialist | F15: HQ - Floor 2 | G15: +974 6406 2020 | H15: Fatima Al-Ali | I15: Active | J15: =COUNTIF('Asset Register'!P:P,B15) -> 2

Sheet Transactions
A1: 🔄 ASSET TRANSACTIONS
A2: Complete check-in / check-out log for all asset movements
A3: Transaction ID | B3: Date | C3: Asset ID | D3: Asset Name | E3: Transaction Type | F3: Employee ID | G3: Employee Name | H3: Department | I3: Issued By | J3: Expected Return | K3: Actual Return | L3: Days Out | M3: Status | N3: Condition Out | O3: Condition In | P3: Notes
A4: TXN-0001 | B4: 45994 | C4: DES-001 | D4: Lenovo Desktop | E4: Check-In | F4: EMP-007 | G4: Tariq Nasser | H4: Executive | I4: Hessa Al-Zaabi | K4: 46017 | L4: =IF(K4<>"",K4-B4,TODAY()-B4) -> 23 | M4: Closed | N4: Excellent | O4: Poor
A5: TXN-0002 | B5: 45855 | C5: MON-001 | D5: Lenovo Monitor | E5: Check-Out | F5: EMP-006 | G5: Layla Ibrahim | H5: Legal | I5: Omar Yusuf | J5: 46084 | L5: =IF(K5<>"",K5-B5,TODAY()-B5) -> 244 | M5: Open | N5: Poor
A6: TXN-0003 | B6: 45824 | C6: PRN-001 | D6: Apple Printer | E6: Transfer | F6: EMP-010 | G6: Hessa Al-Zaabi | H6: HR | I6: Fatima Al-Ali | J6: 46103 | L6: =IF(K6<>"",K6-B6,TODAY()-B6) -> 275 | M6: Closed | N6: Good
A7: TXN-0004 | B7: 45960 | C7: SRV-001 | D7: Cisco Server | E7: Check-In | F7: EMP-008 | G7: Mona Salem | H7: IT | I7: Ahmed Al-Rashid | K7: 45973 | L7: =IF(K7<>"",K7-B7,TODAY()-B7) -> 13 | M7: Closed | N7: Fair | O7: Poor
A8: TXN-0005 | B8: 46015 | C8: NET-001 | D8: Dell Network | E8: Check-In | F8: EMP-003 | G8: Khalid Hassan | H8: Operations | I8: Hessa Al-Zaabi | K8: 46033 | L8: =IF(K8<>"",K8-B8,TODAY()-B8) -> 18 | M8: Closed | N8: Excellent | O8: Poor
A9: TXN-0006 | B9: 45796 | C9: PHN-001 | D9: Apple Phone | E9: Transfer | F9: EMP-011 | G9: Rashed Khalil | H9: Operations | I9: Ahmed Al-Rashid | J9: 45868 | L9: =IF(K9<>"",K9-B9,TODAY()-B9) -> 303 | M9: Closed | N9: Poor
A10: TXN-0007 | B10: 46030 | C10: TAB-001 | D10: Samsung Tablet | E10: Check-In | F10: EMP-003 | G10: Khalid Hassan | H10: Operations | I10: Ahmed Al-Rashid | K10: 46039 | L10: =IF(K10<>"",K10-B10,TODAY()-B10) -> 9 | M10: Closed | N10: Poor | O10: Fair
A11: TXN-0008 | B11: 45991 | C11: PRJ-001 | D11: Dell Projector | E11: Check-In | F11: EMP-006 | G11: Layla Ibrahim | H11: Legal | I11: Layla Ibrahim | K11: 46016 | L11: =IF(K11<>"",K11-B11,TODAY()-B11) -> 25 | M11: Closed | N11: Poor | O11: Fair
A12: TXN-0009 | B12: 45884 | C12: UPS-001 | D12: Samsung UPS | E12: Check-Out | F12: EMP-002 | G12: Sara Mohammed | H12: HR | I12: Mona Salem | J12: 45923 | L12: =IF(K12<>"",K12-B12,TODAY()-B12) -> 215 | M12: Open | N12: Excellent
A13: TXN-0010 | B13: 45920 | C13: LAP-002 | D13: Cisco Laptop | E13: Check-Out | F13: EMP-011 | G13: Rashed Khalil | H13: Operations | I13: Sara Mohammed | J13: 46283 | L13: =IF(K13<>"",K13-B13,TODAY()-B13) -> 179 | M13: Open | N13: Excellent
A14: TXN-0011 | B14: 46084 | C14: DES-002 | D14: Samsung Desktop | E14: Check-Out | F14: EMP-004 | G14: Fatima Al-Ali | H14: Marketing | I14: Ahmed Al-Rashid | J14: 46432 | L14: =IF(K14<>"",K14-B14,TODAY()-B14) -> 15 | M14: Open | N14: Good
A15: TXN-0012 | B15: 45977 | C15: MON-002 | D15: Samsung Monitor | E15: Check-Out | F15: EMP-008 | G15: Mona Salem | H15: IT | I15: Rashed Khalil | J15: 46065 | L15: =IF(K15<>"",K15-B15,TODAY()-B15) -> 122 | M15: Open | N15: Good
A16: TXN-0013 | B16: 45861 | C16: PRN-002 | D16: Samsung Printer | E16: Check-Out | F16: EMP-006 | G16: Layla Ibrahim | H16: Legal | I16: Khalid Hassan | J16: 46201 | L16: =IF(K16<>"",K16-B16,TODAY()-B16) -> 238 | M16: Open | N16: Excellent
A17: TXN-0014 | B17: 46016 | C17: SRV-002 | D17: HP Server | E17: Check-Out | F17: EMP-002 | G17: Sara Mohammed | H17: HR | I17: Hessa Al-Zaabi | J17: 46059 | L17: =IF(K17<>"",K17-B17,TODAY()-B17) -> 83 | M17: Open | N17: Fair
A18: TXN-0015 | B18: 45805 | C18: NET-002 | D18: Apple Network | E18: Check-In | F18: EMP-007 | G18: Tariq Nasser | H18: Executive | I18: Noura Hamdan | K18: 45812 | L18: =IF(K18<>"",K18-B18,TODAY()-B18) -> 7 | M18: Closed | N18: Excellent | O18: Good
A19: TXN-0016 | B19: 46047 | C19: PHN-002 | D19: Samsung Phone | E19: Check-Out | F19: EMP-011 | G19: Rashed Khalil | H19: Operations | I19: Hessa Al-Zaabi | J19: 46138 | L19: =IF(K19<>"",K19-B19,TODAY()-B19) -> 52 | M19: Open | N19: Excellent
A20: TXN-0017 | B20: 45922 | C20: TAB-002 | D20: Apple Tablet | E20: Transfer | F20: EMP-007 | G20: Tariq Nasser | H20: Executive | I20: Rashed Khalil | J20: 46141 | L20: =IF(K20<>"",K20-B20,TODAY()-B20) -> 177 | M20: Closed | N20: Excellent
A21: TXN-0018 | B21: 45840 | C21: PRJ-002 | D21: Cisco Projector | E21: Check-Out | F21: EMP-001 | G21: Ahmed Al-Rashid | H21: Finance | I21: Tariq Nasser | J21: 46120 | L21: =IF(K21<>"",K21-B21,TODAY()-B21) -> 259 | M21: Open | N21: Excellent
A22: TXN-0019 | B22: 45878 | C22: UPS-002 | D22: Dell UPS | E22: Check-Out | F22: EMP-011 | G22: Rashed Khalil | H22: Operations | I22: Mona Salem | J22: 45986 | L22: =IF(K22<>"",K22-B22,TODAY()-B22) -> 221 | M22: Open | N22: Poor
A23: TXN-0020 | B23: 46009 | C23: LAP-003 | D23: HP Laptop | E23: Transfer | F23: EMP-011 | G23: Rashed Khalil | H23: Operations | I23: Omar Yusuf | J23: 46354 | L23: =IF(K23<>"",K23-B23,TODAY()-B23) -> 90 | M23: Closed | N23: Poor
A24: TXN-0021 | B24: 45861 | C24: DES-003 | D24: Samsung Desktop | E24: Check-In | F24: EMP-012 | G24: Noura Hamdan | H24: Marketing | I24: Hessa Al-Zaabi | K24: 45870 | L24: =IF(K24<>"",K24-B24,TODAY()-B24) -> 9 | M24: Closed | N24: Fair | O24: Good
A25: TXN-0022 | B25: 46055 | C25: MON-003 | D25: Lenovo Monitor | E25: Check-Out | F25: EMP-008 | G25: Mona Salem | H25: IT | I25: Fatima Al-Ali | J25: 46322 | L25: =IF(K25<>"",K25-B25,TODAY()-B25) -> 44 | M25: Open | N25: Poor
A26: TXN-0023 | B26: 45927 | C26: PRN-003 | D26: Dell Printer | E26: Check-Out | F26: EMP-008 | G26: Mona Salem | H26: IT | I26: Layla Ibrahim | J26: 46050 | L26: =IF(K26<>"",K26-B26,TODAY()-B26) -> 172 | M26: Open | N26: Poor
A27: TXN-0024 | B27: 45991 | C27: SRV-003 | D27: Lenovo Server | E27: Check-Out | F27: EMP-005 | G27: Omar Yusuf | H27: Sales | I27: Layla Ibrahim | J27: 46164 | L27: =IF(K27<>"",K27-B27,TODAY()-B27) -> 108 | M27: Open | N27: Fair
A28: TXN-0025 | B28: 45815 | C28: NET-003 | D28: Samsung Network | E28: Check-Out | F28: EMP-009 | G28: Yousef Al-Mansoori | H28: Finance | I28: Fatima Al-Ali | J28: 45888 | L28: =IF(K28<>"",K28-B28,TODAY()-B28) -> 284 | M28: Open | N28: Good
A29: TXN-0026 | B29: 45891 | C29: PHN-003 | D29: Apple Phone | E29: Check-In | F29: EMP-009 | G29: Yousef Al-Mansoori | H29: Finance | I29: Fatima Al-Ali | K29: 45914 | L29: =IF(K29<>"",K29-B29,TODAY()-B29) -> 23 | M29: Closed | N29: Poor | O29: Poor
A30: TXN-0027 | B30: 45870 | C30: TAB-003 | D30: Dell Tablet | E30: Check-Out | F30: EMP-002 | G30: Sara Mohammed | H30: HR | I30: Omar Yusuf | J30: 46013 | L30: =IF(K30<>"",K30-B30,TODAY()-B30) -> 229 | M30: Open | N30: Poor
A31: TXN-0028 | B31: 45745 | C31: PRJ-003 | D31: Samsung Projector | E31: Check-Out | F31: EMP-005 | G31: Omar Yusuf | H31: Sales | I31: Rashed Khalil | J31: 46072 | L31: =IF(K31<>"",K31-B31,TODAY()-B31) -> 354 | M31: Open | N31: Fair
A32: TXN-0029 | B32: 45857 | C32: UPS-003 | D32: Lenovo UPS | E32: Transfer | F32: EMP-009 | G32: Yousef Al-Mansoori | H32: Finance | I32: Layla Ibrahim | J32: 46104 | L32: =IF(K32<>"",K32-B32,TODAY()-B32) -> 242 | M32: Closed | N32: Fair
A33: TXN-0030 | B33: 45919 | C33: LAP-004 | D33: Dell Laptop | E33: Check-In | F33: EMP-005 | G33: Omar Yusuf | H33: Sales | I33: Omar Yusuf | K33: 45928 | L33: =IF(K33<>"",K33-B33,TODAY()-B33) -> 9 | M33: Closed | N33: Good | O33: Excellent
A34: TXN-0031 | B34: 46001 | C34: DES-004 | D34: Samsung Desktop | E34: Check-Out | F34: EMP-002 | G34: Sara Mohammed | H34: HR | I34: Noura Hamdan | J34: 46305 | L34: =IF(K34<>"",K34-B34,TODAY()-B34) -> 98 | M34: Open | N34: Good
A35: TXN-0032 | B35: 46001 | C35: MON-004 | D35: Dell Monitor | E35: Check-Out | F35: EMP-012 | G35: Noura Hamdan | H35: Marketing | I35: Mona Salem | J35: 46172 | L35: =IF(K35<>"",K35-B35,TODAY()-B35) -> 98 | M35: Open | N35: Fair
A36: TXN-0033 | B36: 46048 | C36: PRN-004 | D36: Cisco Printer | E36: Check-Out | F36: EMP-005 | G36: Omar Yusuf | H36: Sales | I36: Fatima Al-Ali | J36: 46262 | L36: =IF(K36<>"",K36-B36,TODAY()-B36) -> 51 | M36: Open | N36: Good
A37: TXN-0034 | B37: 45945 | C37: SRV-004 | D37: HP Server | E37: Check-Out | F37: EMP-012 | G37: Noura Hamdan | H37: Marketing | I37: Yousef Al-Mansoori | J37: 46039 | L37: =IF(K37<>"",K37-B37,TODAY()-B37) -> 154 | M37: Open | N37: Fair
A38: TXN-0035 | B38: 46076 | C38: NET-004 | D38: Dell Network | E38: Check-Out | F38: EMP-009 | G38: Yousef Al-Mansoori | H38: Finance | I38: Omar Yusuf | J38: 46170 | L38: =IF(K38<>"",K38-B38,TODAY()-B38) -> 23 | M38: Open | N38: Poor
A39: TXN-0036 | B39: 46047 | C39: PHN-004 | D39: Samsung Phone | E39: Check-Out | F39: EMP-010 | G39: Hessa Al-Zaabi | H39: HR | I39: Omar Yusuf | J39: 46317 | L39: =IF(K39<>"",K39-B39,TODAY()-B39) -> 52 | M39: Open | N39: Poor
A40: TXN-0037 | B40: 45874 | C40: TAB-004 | D40: Lenovo Tablet | E40: Check-Out | F40: EMP-003 | G40: Khalid Hassan | H40: Operations | I40: Ahmed Al-Rashid | J40: 46033 | L40: =IF(K40<>"",K40-B40,TODAY()-B40) -> 225 | M40: Open | N40: Poor
...

Sheet Maintenance
A1: 🔧 MAINTENANCE TRACKER
A2: Log and monitor all repair, service, and maintenance activities
A3: Maintenance ID | B3: Asset ID | C3: Asset Name | D3: Category | E3: Department | F3: Issue Description | G3: Priority | H3: Maintenance Type | I3: Technician | J3: Date Reported | K3: Date Started | L3: Date Completed | M3: Duration (Days) | N3: Cost (QAR) | O3: Vendor / Provider | P3: Parts Replaced | Q3: Status | R3: Resolution Notes
A4: MNT-0001 | B4: MON-001 | C4: Lenovo Monitor | D4: Monitor | E4: HR | F4: System crashes | G4: Low | H4: Upgrade | I4: Vendor - HP Support | J4: 46022 | K4: 46025 | L4: 46035 | M4: =IF(L4<>"",L4-K4,IF(K4<>"",TODAY()-K4,"")) -> 10 | N4: 167.45 | O4: Samsung | Q4: Completed
A5: MNT-0002 | B5: SRV-001 | C5: Cisco Server | D5: Server | E5: Marketing | F5: Battery not charging | G5: High | H5: Data Recovery | I5: Sara IT Dept | J5: 46031 | K5: 46031 | M5: =IF(L5<>"",L5-K5,IF(K5<>"",TODAY()-K5,"")) -> 68 | N5: 0 | O5: Cisco | Q5: Completed
A6: MNT-0003 | B6: PHN-001 | C6: Apple Phone | D6: Phone | E6: Legal | F6: Battery not charging | G6: High | H6: Hardware Repair | I6: Vendor - HP Support | J6: 45983 | K6: 45986 | M6: =IF(L6<>"",L6-K6,IF(K6<>"",TODAY()-K6,"")) -> 113 | N6: 0 | O6: Apple | Q6: Completed
A7: MNT-0004 | B7: PRJ-001 | C7: Dell Projector | D7: Projector | E7: IT | F7: Overheating | G7: Low | H7: Hardware Repair | I7: Sara IT Dept | J7: 46031 | K7: 46032 | L7: 46041 | M7: =IF(L7<>"",L7-K7,IF(K7<>"",TODAY()-K7,"")) -> 9 | N7: 488.38 | O7: HP Enterprise | Q7: Completed
A8: MNT-0005 | B8: LAP-002 | C8: Cisco Laptop | D8: Laptop | E8: HR | F8: Overheating | G8: High | H8: Hardware Repair | I8: Ahmed IT Dept | J8: 46056 | K8: 46058 | L8: 46072 | M8: =IF(L8<>"",L8-K8,IF(K8<>"",TODAY()-K8,"")) -> 14 | N8: 1159.95 | O8: Apple | Q8: Completed
A9: MNT-0006 | B9: MON-002 | C9: Samsung Monitor | D9: Monitor | E9: Marketing | F9: Fan noise | G9: Critical | H9: Upgrade | I9: Vendor - Dell Support | J9: 45919 | K9: 45922 | L9: 45931 | M9: =IF(L9<>"",L9-K9,IF(K9<>"",TODAY()-K9,"")) -> 9 | N9: 1102.96 | O9: Lenovo | Q9: Completed
A10: MNT-0007 | B10: SRV-002 | C10: HP Server | D10: Server | E10: Legal | F10: Battery not charging | G10: Critical | H10: Upgrade | I10: Vendor - Dell Support | J10: 45944 | K10: 45946 | M10: =IF(L10<>"",L10-K10,IF(K10<>"",TODAY()-K10,"")) -> 153 | N10: 0 | O10: Samsung | Q10: Completed
A11: MNT-0008 | B11: PHN-002 | C11: Samsung Phone | D11: Phone | E11: IT | F11: Printer jam | G11: Critical | H11: Data Recovery | I11: Vendor - Dell Support | J11: 45951 | K11: 45951 | L11: 45954 | M11: =IF(L11<>"",L11-K11,IF(K11<>"",TODAY()-K11,"")) -> 3 | N11: 967.48 | O11: Samsung | Q11: Completed
A12: MNT-0009 | B12: PRJ-002 | C12: Cisco Projector | D12: Projector | E12: HR | F12: Fan noise | G12: Medium | H12: Software Issue | I12: External Tech | J12: 45987 | K12: 45990 | L12: 45998 | M12: =IF(L12<>"",L12-K12,IF(K12<>"",TODAY()-K12,"")) -> 8 | N12: 728.52 | O12: Apple | Q12: Completed
A13: MNT-0010 | B13: LAP-003 | C13: HP Laptop | D13: Laptop | E13: Marketing | F13: Keyboard malfunction | G13: Critical | H13: Software Issue | I13: Vendor - Dell Support | J13: 45993 | K13: 45996 | M13: =IF(L13<>"",L13-K13,IF(K13<>"",TODAY()-K13,"")) -> 103 | N13: 0 | O13: Epson | Q13: Open
A14: MNT-0011 | B14: MON-003 | C14: Lenovo Monitor | D14: Monitor | E14: Legal | F14: System crashes | G14: Critical | H14: Upgrade | I14: Ahmed IT Dept | J14: 46018 | K14: 46020 | L14: 46033 | M14: =IF(L14<>"",L14-K14,IF(K14<>"",TODAY()-K14,"")) -> 13 | N14: 838.14 | O14: Cisco | Q14: Completed
A15: MNT-0012 | B15: SRV-003 | C15: Lenovo Server | D15: Server | E15: IT | F15: Screen flickering | G15: Low | H15: Upgrade | I15: Ahmed IT Dept | J15: 46050 | K15: 46052 | L15: 46060 | M15: =IF(L15<>"",L15-K15,IF(K15<>"",TODAY()-K15,"")) -> 8 | N15: 1269.55 | O15: Epson | Q15: Completed
A16: MNT-0013 | B16: PHN-003 | C16: Apple Phone | D16: Phone | E16: HR | F16: Screen flickering | G16: High | H16: Preventive Maintenance | I16: External Tech | J16: 46065 | K16: 46067 | L16: 46079 | M16: =IF(L16<>"",L16-K16,IF(K16<>"",TODAY()-K16,"")) -> 12 | N16: 995.19 | O16: Dell Technologies | Q16: Completed
A17: MNT-0014 | B17: PRJ-003 | C17: Samsung Projector | D17: Projector | E17: Marketing | F17: Printer jam | G17: High | H17: Data Recovery | I17: Sara IT Dept | J17: 46019 | K17: 46019 | L17: 46021 | M17: =IF(L17<>"",L17-K17,IF(K17<>"",TODAY()-K17,"")) -> 2 | N17: 488.17 | O17: Epson | Q17: Completed
A18: MNT-0015 | B18: LAP-004 | C18: Dell Laptop | D18: Laptop | E18: Legal | F18: Battery not charging | G18: Low | H18: Hardware Repair | I18: Sara IT Dept | J18: 45971 | K18: 45973 | L18: 45978 | M18: =IF(L18<>"",L18-K18,IF(K18<>"",TODAY()-K18,"")) -> 5 | N18: 860.21 | O18: Lenovo | Q18: Completed
A19: MNT-0016 | B19: MON-004 | C19: Dell Monitor | D19: Monitor | E19: IT | F19: Fan noise | G19: High | H19: Upgrade | I19: External Tech | J19: 46061 | K19: 46064 | M19: =IF(L19<>"",L19-K19,IF(K19<>"",TODAY()-K19,"")) -> 35 | N19: 0 | O19: Epson | Q19: Completed
A20: MNT-0017 | B20: SRV-004 | C20: HP Server | D20: Server | E20: HR | F20: Battery not charging | G20: Medium | H20: Upgrade | I20: Vendor - Dell Support | J20: 45969 | K20: 45971 | L20: 45976 | M20: =IF(L20<>"",L20-K20,IF(K20<>"",TODAY()-K20,"")) -> 5 | N20: 1465.8 | O20: Epson | Q20: Completed
A21: MNT-0018 | B21: PHN-004 | C21: Samsung Phone | D21: Phone | E21: Marketing | F21: Printer jam | G21: Low | H21: Software Issue | I21: Vendor - HP Support | J21: 45961 | K21: 45964 | L21: 45973 | M21: =IF(L21<>"",L21-K21,IF(K21<>"",TODAY()-K21,"")) -> 9 | N21: 1537.6 | O21: Lenovo | Q21: Completed
A22: MNT-0019 | B22: PRJ-004 | C22: Samsung Projector | D22: Projector | E22: Legal | F22: Fan noise | G22: Medium | H22: Software Issue | I22: Sara IT Dept | J22: 45952 | K22: 45955 | M22: =IF(L22<>"",L22-K22,IF(K22<>"",TODAY()-K22,"")) -> 144 | N22: 0 | O22: Dell Technologies | Q22: Open
A23: MNT-0020 | B23: LAP-005 | C23: Samsung Laptop | D23: Laptop | E23: IT | F23: Keyboard malfunction | G23: Low | H23: Data Recovery | I23: Vendor - HP Support | J23: 46000 | K23: 46001 | L23: 46002 | M23: =IF(L23<>"",L23-K23,IF(K23<>"",TODAY()-K23,"")) -> 1 | N23: 296.18 | O23: Cisco | Q23: Completed
A24: MNT-0021 | B24: MON-005 | C24: Samsung Monitor | D24: Monitor | E24: HR | F24: Keyboard malfunction | G24: Critical | H24: Upgrade | I24: Ahmed IT Dept | J24: 45964 | K24: 45967 | M24: =IF(L24<>"",L24-K24,IF(K24<>"",TODAY()-K24,"")) -> 132 | N24: 0 | O24: Lenovo | Q24: Completed
A25: MNT-0022 | B25: SRV-005 | C25: Samsung Server | D25: Server | E25: Marketing | F25: Slow performance | G25: Critical | H25: Upgrade | I25: Vendor - Dell Support | J25: 46012 | K25: 46015 | L25: 46029 | M25: =IF(L25<>"",L25-K25,IF(K25<>"",TODAY()-K25,"")) -> 14 | N25: 690.7 | O25: Samsung | Q25: Completed
A26: MNT-0023 | B26: PHN-005 | C26: Lenovo Phone | D26: Phone | E26: Legal | F26: System crashes | G26: Low | H26: Preventive Maintenance | I26: Vendor - HP Support | J26: 45960 | K26: 45960 | L26: 45964 | M26: =IF(L26<>"",L26-K26,IF(K26<>"",TODAY()-K26,"")) -> 4 | N26: 1280.76 | O26: Apple | Q26: Completed
A27: MNT-0024 | B27: PRJ-005 | C27: Lenovo Projector | D27: Projector | E27: IT | F27: Network connectivity issue | G27: Critical | H27: Upgrade | I27: Ahmed IT Dept | J27: 45936 | K27: 45936 | L27: 45948 | M27: =IF(L27<>"",L27-K27,IF(K27<>"",TODAY()-K27,"")) -> 12 | N27: 633.96 | O27: Dell Technologies | Q27: Completed
A28: MNT-0025 | B28: LAP-001 | C28: Samsung Laptop | D28: Laptop | E28: IT | F28: Screen flickering | G28: Medium | H28: Hardware Repair | I28: Vendor - Dell Support | J28: 46007 | K28: 46009 | L28: 46013 | M28: =IF(L28<>"",L28-K28,IF(K28<>"",TODAY()-K28,"")) -> 4 | N28: 1085.77 | O28: Cisco | Q28: Completed

Sheet Lookup Tables
A1: 📋 LOOKUP TABLES & REFERENCE DATA
A2: Centralised dropdown values – edit here to update all dropdowns across the workbook
A4: Categories | C4: Statuses | E4: Departments | G4: Locations | I4: Conditions | K4: Priorities | M4: Maint. Types | O4: Tx Types | Q4: Asset ID Prefixes | R4: Prefix
A5: Laptop | C5: In Use | E5: IT | G5: HQ - Floor 1 | I5: Excellent | K5: Critical | M5: Hardware Repair | O5: Check-Out | Q5: Laptop | R5: LAP
A6: Desktop | C6: Available | E6: Finance | G6: HQ - Floor 2 | I6: Good | K6: High | M6: Software Issue | O6: Check-In | Q6: Desktop | R6: DES
A7: Monitor | C7: Under Repair | E7: HR | G7: HQ - Floor 3 | I7: Fair | K7: Medium | M7: Preventive Maintenance | O7: Transfer | Q7: Monitor | R7: MON
A8: Printer | C8: Retired | E8: Operations | G8: Branch - Dubai | I8: Poor | K8: Low | M8: Upgrade | O8: Return | Q8: Printer | R8: PRN
A9: Server | C9: Lost/Stolen | E9: Marketing | G9: Branch - Abu Dhabi | M9: Network Issue | O9: Write-Off | Q9: Server | R9: SRV
A10: Network | C10: In Storage | E10: Sales | G10: Data Center | M10: Data Recovery | Q10: Network | R10: NET
A11: Phone | E11: Legal | G11: Warehouse | Q11: Phone | R11: PHN
A12: Tablet | E12: Executive | Q12: Tablet | R12: TAB
A13: Projector | Q13: Projector | R13: PRJ
A14: UPS | Q14: UPS | R14: UPS

Sheet Warranty Alerts
A1: ⚠️ WARRANTY ALERTS
A2: Assets with expiring or expired warranties – review and renew as needed
A3: Asset ID | B3: Asset Name | C3: Category | D3: Department | E3: Warranty End | F3: Days Remaining | G3: Alert Level | H3: Vendor | I3: Serial Number | J3: Action Required
A4: ℹ️ This sheet uses formulas to pull warranty data from Asset Register. Use FILTER or manual refresh. Below is a static snapshot for reference.
A5: NET-004 | B5: Dell Network | C5: Network | D5: Operations | E5: 45303 | F5: -796 | G5: ❌ Expired | H5: HP Enterprise | I5: SN88183110 | J5: Review & Renew
A6: SRV-004 | B6: HP Server | C6: Server | D6: HR | E6: 45305 | F6: -794 | G6: ❌ Expired | H6: Cisco | I6: SN69302158 | J6: Review & Renew
A7: SRV-002 | B7: HP Server | C7: Server | D7: Legal | E7: 45330 | F7: -769 | G7: ❌ Expired | H7: Cisco | I7: SN31682744 | J7: Review & Renew
A8: PRJ-003 | B8: Samsung Projector | C8: Projector | D8: Marketing | E8: 45364 | F8: -735 | G8: ❌ Expired | H8: Apple | I8: SN85863473 | J8: Review & Renew
A9: LAP-004 | B9: Dell Laptop | C9: Laptop | D9: Legal | E9: 45398 | F9: -701 | G9: ❌ Expired | H9: Apple | I9: SN38609087 | J9: Review & Renew
A10: PRN-002 | B10: Samsung Printer | C10: Printer | D10: Sales | E10: 45409 | F10: -690 | G10: ❌ Expired | H10: Cisco | I10: SN45351479 | J10: Review & Renew
A11: NET-003 | B11: Samsung Network | C11: Network | D11: Finance | E11: 45438 | F11: -661 | G11: ❌ Expired | H11: Apple | I11: SN98834863 | J11: Review & Renew
A12: SRV-005 | B12: Samsung Server | C12: Server | D12: Marketing | E12: 45610 | F12: -489 | G12: ❌ Expired | H12: Cisco | I12: SN53779528 | J12: Review & Renew
A13: NET-005 | B13: Cisco Network | C13: Network | D13: Sales | E13: 45677 | F13: -422 | G13: ❌ Expired | H13: Apple | I13: SN64502486 | J13: Review & Renew
A14: PRN-005 | B14: Apple Printer | C14: Printer | D14: Operations | E14: 45758 | F14: -341 | G14: ❌ Expired | H14: Samsung | I14: SN19391725 | J14: Review & Renew
A15: DES-005 | B15: Cisco Desktop | C15: Desktop | D15: Finance | E15: 45792 | F15: -307 | G15: ❌ Expired | H15: Cisco | I15: SN56397338 | J15: Review & Renew
A16: UPS-003 | B16: Lenovo UPS | C16: UPS | D16: Sales | E16: 45820 | F16: -279 | G16: ❌ Expired | H16: Epson | I16: SN96637649 | J16: Review & Renew
... A32: TAB-001 | B32: Samsung Tablet | C32: Tablet | D32: Executive | E32: 46218 | F32: 119 | G32: 🟡 Notice | H32: Samsung | I32: SN31931511 | J32: Monitor

Sheet Audit Log
A1: 📝 AUDIT LOG
A2: Automatic or manual record of all changes made to this workbook
A3: Log ID | B3: Timestamp | C3: User | D3: Action | E3: Sheet | F3: Record ID | G3: Field Changed | H3: Old Value | I3: New Value | J3: IP Address / Notes
A4: LOG-00001 | B4: 46056 | C4: Khalid Hassan | D4: INSERT | E4: Asset Register | F4: AST-006 | G4: Condition | H4: IT | I4: Excellent | J4: 192.168.1.184
A5: LOG-00002 | B5: 46084 | C5: Mona Salem | D5: CHECK-IN | E5: Asset Register | F5: AST-015 | G5: Warranty End | H5: Ahmed Al-Rashid | I5: Finance | J5: 192.168.1.75
A6: LOG-00003 | B6: 46057 | C6: Ahmed Al-Rashid | D6: CHECK-OUT | E6: Transactions | F6: AST-044 | G6: Condition | H6: In Use | I6: In Use | J6: 192.168.1.123
A7: LOG-00004 | B7: 46039 | C7: Layla Ibrahim | D7: CHECK-IN | E7: Transactions | F7: AST-041 | G7: Warranty End | H7: Ahmed Al-Rashid | I7: Finance | J7: 192.168.1.87
A8: LOG-00005 | B8: 46087 | C8: Tariq Nasser | D8: CHECK-OUT | E8: Asset Register | F8: AST-016 | G8: Warranty End | H8: Good | I8: Sara Mohammed | J8: 192.168.1.157
A9: LOG-00006 | B9: 46081 | C9: Noura Hamdan | D9: DELETE | E9: Asset Register | F9: AST-043 | G9: Warranty End | H9: Ahmed Al-Rashid | I9: In Use | J9: 192.168.1.154
A10: LOG-00007 | B10: 46044 | C10: Rashed Khalil | D10: STATUS CHANGE | E10: Asset Register | F10: AST-039 | G10: Warranty End | H10: Ahmed Al-Rashid | I10: Under Repair | J10: 192.168.1.165
A11: LOG-00008 | B11: 46048 | C11: Layla Ibrahim | D11: INSERT | E11: Maintenance | F11: AST-013 | G11: Condition | H11: Ahmed Al-Rashid | I11: Under Repair | J11: 192.168.1.170
A12: LOG-00009 | B12: 46093 | C12: Rashed Khalil | D12: STATUS CHANGE | E12: Asset Register | F12: AST-020 | G12: Warranty End | H12: Available | I12: Excellent | J12: 192.168.1.103
A13: LOG-00010 | B13: 46053 | C13: Khalid Hassan | D13: UPDATE | E13: Transactions | F13: AST-021 | G13: Warranty End | H13: In Use | I13: Under Repair | J13: 192.168.1.43
A14: LOG-00011 | B14: 46049 | C14: Yousef Al-Mansoori | D14: DELETE | E14: Maintenance | F14: AST-033 | G14: Department | H14: In Use | I14: Sara Mohammed | J14: 192.168.1.133
A15: LOG-00012 | B15: 46048 | C15: Omar Yusuf | D15: STATUS CHANGE | E15: Transactions | F15: AST-008 | G15: Warranty End | H15: Available | I15: Under Repair | J15: 192.168.1.67
... A23: LOG-00020 | B23: 46039 | C23: Omar Yusuf | D23: UPDATE | E23: Maintenance | F23: AST-024 | G23: Assigned To | H23: IT | I23: Finance | J23: 192.168.1.70

Sheet Instructions
A1: 📖 INSTRUCTIONS & HELP GUIDE
A2: How to use the IT Asset Management Tracker – read before making changes
A4: GETTING STARTED
A5: 1. Asset Register | B5: Primary sheet for all assets. Add new assets starting from row 4. Asset IDs follow format: LAP-001, PRN-002 etc.
A6: 2. Users Sheet | B6: Maintain an up-to-date list of all employees who can be assigned assets. Required for dropdown lookups.
A7: 3. Transactions | B7: Log every check-out or check-in here. Transaction ID format: TXN-0001
A8: 4. Maintenance | B8: Log all repairs and maintenance. Link to Asset ID. Priority levels: Critical > High > Medium > Low
A10: ASSET ID FORMAT
A11: Format | B11: PREFIX-NNN (e.g., LAP-001) | Prefix = 3-letter category code | NNN = 3-digit sequential number
A12: Prefixes | B12: LAP=Laptop | DES=Desktop | MON=Monitor | PRN=Printer | SRV=Server | NET=Network | PHN=Phone | TAB=Tablet | PRJ=Projector | UPS=UPS
A13: Auto-numbering | B13: Check the last used number in Asset Register column A and increment by 1 for each new asset in that category
A15: COLOR CODING
A16: 🟢 Green | B16: Available / Active / Good status
A17: 🔵 Blue | B17: In Use / Open transaction
A18: 🟠 Orange | B18: Under Repair / Warning / High priority
A19: 🔴 Red | B19: Retired / Expired / Critical / Lost
A20: 🟡 Yellow | B20: Expiring Soon / Medium priority / Pending
A22: DATA VALIDATION
A23: Dropdowns | B23: All dropdown values are managed in the 'Lookup Tables' sheet. Edit values there to update dropdowns everywhere.
A24: Dates | B24: Always enter dates in DD-MMM-YYYY format (e.g., 15-Jan-2025) or use the date picker
A25: Currency | B25: Enter amounts in QAR without symbols. Format is applied automatically.
A27: BEST PRACTICES
A28: Never delete rows | B28: Mark assets as 'Retired' instead of deleting. This preserves history and audit trail.
A29: Regular updates | B29: Update asset status and assignment in real-time for accurate dashboard data.
A30: Warranty review | B30: Check 'Warranty Alerts' sheet monthly to proactively renew warranties.
A31: Audit log | B31: For manual changes to critical fields, record them in the Audit Log sheet.
A32: Backups | B32: Save a dated backup copy at the end of each month: IT_Assets_YYYY-MM.xlsx
A34: FORMULAS REFERENCE
A35: Warranty Status | B35: =IF(L4="","N/A",IF(L4<TODAY(),"Expired",IF(L4<TODAY()+90,"Expiring Soon","Active"))) -> N/A
A36: Days Out | B36: =IF(K4<>"",K4-B4,TODAY()-B4) -> 46099
A37: Asset Count (User) | B37: =COUNTIF('Asset Register'!P:P, B4) -> 0
A38: Category Total | B38: =COUNTIF('Asset Register'!C:C, A18) -> 0
A39: Dept. Maintenance Cost | B39: =SUMIF(Maintenance!E:E, I18, Maintenance!N:N) -> 0
A41: GOOGLE SHEETS NOTES
A42: QUERY equivalent | B42: Google Sheets: =QUERY(sheet, "SELECT A,B,C,Q WHERE Q=In Use", 1)
A43: FILTER equivalent | B43: Google Sheets: =FILTER(A4:T500, Q4:Q500="Available")
A44: Apps Script | B44: Use Apps Script for auto-email on warranty expiry, auto-ID generation, and change logging.
